Internal Server Error: /ai/generate/1/
Traceback (most recent call last):
  File "/home/s1gm9/Documents/Projects/DIGIMANAGER/venv/lib/python3.13/site-packages/django/core/handlers/exception.py", line 55, in inner
    response = get_response(request)
  File "/home/s1gm9/Documents/Projects/DIGIMANAGER/venv/lib/python3.13/site-packages/django/core/handlers/base.py", line 197, in _get_response
    response = wrapped_callback(request, *callback_args, **callback_kwargs)
  File "/home/s1gm9/Documents/Projects/DIGIMANAGER/venv/lib/python3.13/site-packages/django/views/decorators/http.py", line 64, in inner
    return func(request, *args, **kwargs)
  File "/home/s1gm9/Documents/Projects/DIGIMANAGER/venv/lib/python3.13/site-packages/django/views/decorators/csrf.py", line 65, in _view_wrapper
    return view_func(request, *args, **kwargs)
  File "/home/s1gm9/Documents/Projects/DIGIMANAGER/DIGIMANAGER/scheduler/views.py", line 37, in generate_ai_image
    from yourapp.utils import generate_image_sd  # or your AI image generation logic
    ^^^^^^^^^^^^^^^^^^^^^^^^^^^^^^^^^^^^^^^^^^^
ModuleNotFoundError: No module named 'yourapp'
"POST /ai/generate/1/ HTTP/1.1" 500 76713
Internal Server Error: /ai/generate/1/
Traceback (most recent call last):
  File "/home/s1gm9/Documents/Projects/DIGIMANAGER/venv/lib/python3.13/site-packages/django/core/handlers/exception.py", line 55, in inner
    response = get_response(request)
  File "/home/s1gm9/Documents/Projects/DIGIMANAGER/venv/lib/python3.13/site-packages/django/core/handlers/base.py", line 197, in _get_response
    response = wrapped_callback(request, *callback_args, **callback_kwargs)
  File "/home/s1gm9/Documents/Projects/DIGIMANAGER/venv/lib/python3.13/site-packages/django/views/decorators/http.py", line 64, in inner
    return func(request, *args, **kwargs)
  File "/home/s1gm9/Documents/Projects/DIGIMANAGER/venv/lib/python3.13/site-packages/django/views/decorators/csrf.py", line 65, in _view_wrapper
    return view_func(request, *args, **kwargs)
  File "/home/s1gm9/Documents/Projects/DIGIMANAGER/DIGIMANAGER/scheduler/views.py", line 37, in generate_ai_image
    from yourapp.utils import generate_image_sd  # or your AI image generation logic
    ^^^^^^^^^^^^^^^^^^^^^^^^^^^^^^^^^^^^^^^^^^^
ModuleNotFoundError: No module named 'yourapp'
"POST /ai/generate/1/ HTTP/1.1" 500 76657
Internal Server Error: /ai/generate/1/
Traceback (most recent call last):
  File "/home/s1gm9/Documents/Projects/DIGIMANAGER/venv/lib/python3.13/site-packages/django/core/handlers/exception.py", line 55, in inner
    response = get_response(request)
  File "/home/s1gm9/Documents/Projects/DIGIMANAGER/venv/lib/python3.13/site-packages/django/core/handlers/base.py", line 197, in _get_response
    response = wrapped_callback(request, *callback_args, **callback_kwargs)
  File "/home/s1gm9/Documents/Projects/DIGIMANAGER/venv/lib/python3.13/site-packages/django/views/decorators/http.py", line 64, in inner
    return func(request, *args, **kwargs)
  File "/home/s1gm9/Documents/Projects/DIGIMANAGER/venv/lib/python3.13/site-packages/django/views/decorators/csrf.py", line 65, in _view_wrapper
    return view_func(request, *args, **kwargs)
  File "/home/s1gm9/Documents/Projects/DIGIMANAGER/DIGIMANAGER/scheduler/views.py", line 37, in generate_ai_image
    from yourapp.utils import generate_image_sd  # or your AI image generation logic
    ^^^^^^^^^^^^^^^^^^^^^^^^^^^^^^^^^^^^^^^^^^^
ModuleNotFoundError: No module named 'yourapp'
"POST /ai/generate/1/ HTTP/1.1" 500 76657
Internal Server Error: /ai/generate/1/
Traceback (most recent call last):
  File "/home/s1gm9/Documents/Projects/DIGIMANAGER/venv/lib/python3.13/site-packages/django/core/handlers/exception.py", line 55, in inner
    response = get_response(request)
  File "/home/s1gm9/Documents/Projects/DIGIMANAGER/venv/lib/python3.13/site-packages/django/core/handlers/base.py", line 197, in _get_response
    response = wrapped_callback(request, *callback_args, **callback_kwargs)
  File "/home/s1gm9/Documents/Projects/DIGIMANAGER/venv/lib/python3.13/site-packages/django/views/decorators/http.py", line 64, in inner
    return func(request, *args, **kwargs)
  File "/home/s1gm9/Documents/Projects/DIGIMANAGER/venv/lib/python3.13/site-packages/django/views/decorators/csrf.py", line 65, in _view_wrapper
    return view_func(request, *args, **kwargs)
  File "/home/s1gm9/Documents/Projects/DIGIMANAGER/DIGIMANAGER/scheduler/views.py", line 42, in generate_ai_image
    from yourapp.utils import generate_image_sd  # or your AI image generation logic
    ^^^^^^^^^^^^^^^^^^^^^^^^^^^^^^^^^^^^^^^^^^^
ModuleNotFoundError: No module named 'yourapp'
"POST /ai/generate/1/ HTTP/1.1" 500 76665
Internal Server Error: /ai/generate/1/
Traceback (most recent call last):
  File "/home/s1gm9/Documents/Projects/DIGIMANAGER/venv/lib/python3.13/site-packages/django/core/handlers/exception.py", line 55, in inner
    response = get_response(request)
  File "/home/s1gm9/Documents/Projects/DIGIMANAGER/venv/lib/python3.13/site-packages/django/core/handlers/base.py", line 197, in _get_response
    response = wrapped_callback(request, *callback_args, **callback_kwargs)
  File "/home/s1gm9/Documents/Projects/DIGIMANAGER/venv/lib/python3.13/site-packages/django/views/decorators/http.py", line 64, in inner
    return func(request, *args, **kwargs)
  File "/home/s1gm9/Documents/Projects/DIGIMANAGER/venv/lib/python3.13/site-packages/django/views/decorators/csrf.py", line 65, in _view_wrapper
    return view_func(request, *args, **kwargs)
  File "/home/s1gm9/Documents/Projects/DIGIMANAGER/DIGIMANAGER/scheduler/views.py", line 42, in generate_ai_image
    from yourapp.utils import generate_image_sd  # or your AI image generation logic
    ^^^^^^^^^^^^^^^^^^^^^^^^^^^^^^^^^^^^^^^^^^^
ModuleNotFoundError: No module named 'yourapp'
"POST /ai/generate/1/ HTTP/1.1" 500 76665
Internal Server Error: /ai/generate/1/
Traceback (most recent call last):
  File "/home/s1gm9/Documents/Projects/DIGIMANAGER/venv/lib/python3.13/site-packages/django/core/handlers/exception.py", line 55, in inner
    response = get_response(request)
  File "/home/s1gm9/Documents/Projects/DIGIMANAGER/venv/lib/python3.13/site-packages/django/core/handlers/base.py", line 197, in _get_response
    response = wrapped_callback(request, *callback_args, **callback_kwargs)
  File "/home/s1gm9/Documents/Projects/DIGIMANAGER/venv/lib/python3.13/site-packages/django/views/decorators/http.py", line 64, in inner
    return func(request, *args, **kwargs)
  File "/home/s1gm9/Documents/Projects/DIGIMANAGER/venv/lib/python3.13/site-packages/django/views/decorators/csrf.py", line 65, in _view_wrapper
    return view_func(request, *args, **kwargs)
  File "/home/s1gm9/Documents/Projects/DIGIMANAGER/DIGIMANAGER/scheduler/views.py", line 42, in generate_ai_image
    from yourapp.utils import generate_image_sd  # or your AI image generation logic
    ^^^^^^^^^^^^^^^^^^^^^^^^^^^^^^^^^^^^^^^^^^^
ModuleNotFoundError: No module named 'yourapp'
"POST /ai/generate/1/ HTTP/1.1" 500 76655
Internal Server Error: /ai/generate/1/
Traceback (most recent call last):
  File "/home/s1gm9/Documents/Projects/DIGIMANAGER/venv/lib/python3.13/site-packages/django/core/handlers/exception.py", line 55, in inner
    response = get_response(request)
  File "/home/s1gm9/Documents/Projects/DIGIMANAGER/venv/lib/python3.13/site-packages/django/core/handlers/base.py", line 197, in _get_response
    response = wrapped_callback(request, *callback_args, **callback_kwargs)
  File "/home/s1gm9/Documents/Projects/DIGIMANAGER/venv/lib/python3.13/site-packages/django/views/decorators/http.py", line 64, in inner
    return func(request, *args, **kwargs)
  File "/home/s1gm9/Documents/Projects/DIGIMANAGER/venv/lib/python3.13/site-packages/django/views/decorators/csrf.py", line 65, in _view_wrapper
    return view_func(request, *args, **kwargs)
  File "/home/s1gm9/Documents/Projects/DIGIMANAGER/DIGIMANAGER/scheduler/views.py", line 42, in generate_ai_image
    from yourapp.utils import generate_image_sd  # or your AI image generation logic
    ^^^^^^^^^^^^^^^^^^^^^^^^^^^^^^^^^^^^^^^^^^^
ModuleNotFoundError: No module named 'yourapp'
"POST /ai/generate/1/ HTTP/1.1" 500 76656
