Internal Server Error: /ai/generate/1/
Traceback (most recent call last):
  File "/home/s1gm9/Documents/Projects/DIGIMANAGER/venv/lib/python3.13/site-packages/django/core/handlers/exception.py", line 55, in inner
    response = get_response(request)
  File "/home/s1gm9/Documents/Projects/DIGIMANAGER/venv/lib/python3.13/site-packages/django/core/handlers/base.py", line 197, in _get_response
    response = wrapped_callback(request, *callback_args, **callback_kwargs)
  File "/home/s1gm9/Documents/Projects/DIGIMANAGER/venv/lib/python3.13/site-packages/django/views/decorators/http.py", line 64, in inner
    return func(request, *args, **kwargs)
  File "/home/s1gm9/Documents/Projects/DIGIMANAGER/venv/lib/python3.13/site-packages/django/views/decorators/csrf.py", line 65, in _view_wrapper
    return view_func(request, *args, **kwargs)
  File "/home/s1gm9/Documents/Projects/DIGIMANAGER/DIGIMANAGER/scheduler/views.py", line 37, in generate_ai_image
    from yourapp.utils import generate_image_sd  # or your AI image generation logic
    ^^^^^^^^^^^^^^^^^^^^^^^^^^^^^^^^^^^^^^^^^^^
ModuleNotFoundError: No module named 'yourapp'
"POST /ai/generate/1/ HTTP/1.1" 500 76713
Internal Server Error: /ai/generate/1/
Traceback (most recent call last):
  File "/home/s1gm9/Documents/Projects/DIGIMANAGER/venv/lib/python3.13/site-packages/django/core/handlers/exception.py", line 55, in inner
    response = get_response(request)
  File "/home/s1gm9/Documents/Projects/DIGIMANAGER/venv/lib/python3.13/site-packages/django/core/handlers/base.py", line 197, in _get_response
    response = wrapped_callback(request, *callback_args, **callback_kwargs)
  File "/home/s1gm9/Documents/Projects/DIGIMANAGER/venv/lib/python3.13/site-packages/django/views/decorators/http.py", line 64, in inner
    return func(request, *args, **kwargs)
  File "/home/s1gm9/Documents/Projects/DIGIMANAGER/venv/lib/python3.13/site-packages/django/views/decorators/csrf.py", line 65, in _view_wrapper
    return view_func(request, *args, **kwargs)
  File "/home/s1gm9/Documents/Projects/DIGIMANAGER/DIGIMANAGER/scheduler/views.py", line 37, in generate_ai_image
    from yourapp.utils import generate_image_sd  # or your AI image generation logic
    ^^^^^^^^^^^^^^^^^^^^^^^^^^^^^^^^^^^^^^^^^^^
ModuleNotFoundError: No module named 'yourapp'
"POST /ai/generate/1/ HTTP/1.1" 500 76657
Internal Server Error: /ai/generate/1/
Traceback (most recent call last):
  File "/home/s1gm9/Documents/Projects/DIGIMANAGER/venv/lib/python3.13/site-packages/django/core/handlers/exception.py", line 55, in inner
    response = get_response(request)
  File "/home/s1gm9/Documents/Projects/DIGIMANAGER/venv/lib/python3.13/site-packages/django/core/handlers/base.py", line 197, in _get_response
    response = wrapped_callback(request, *callback_args, **callback_kwargs)
  File "/home/s1gm9/Documents/Projects/DIGIMANAGER/venv/lib/python3.13/site-packages/django/views/decorators/http.py", line 64, in inner
    return func(request, *args, **kwargs)
  File "/home/s1gm9/Documents/Projects/DIGIMANAGER/venv/lib/python3.13/site-packages/django/views/decorators/csrf.py", line 65, in _view_wrapper
    return view_func(request, *args, **kwargs)
  File "/home/s1gm9/Documents/Projects/DIGIMANAGER/DIGIMANAGER/scheduler/views.py", line 37, in generate_ai_image
    from yourapp.utils import generate_image_sd  # or your AI image generation logic
    ^^^^^^^^^^^^^^^^^^^^^^^^^^^^^^^^^^^^^^^^^^^
ModuleNotFoundError: No module named 'yourapp'
"POST /ai/generate/1/ HTTP/1.1" 500 76657
Internal Server Error: /ai/generate/1/
Traceback (most recent call last):
  File "/home/s1gm9/Documents/Projects/DIGIMANAGER/venv/lib/python3.13/site-packages/django/core/handlers/exception.py", line 55, in inner
    response = get_response(request)
  File "/home/s1gm9/Documents/Projects/DIGIMANAGER/venv/lib/python3.13/site-packages/django/core/handlers/base.py", line 197, in _get_response
    response = wrapped_callback(request, *callback_args, **callback_kwargs)
  File "/home/s1gm9/Documents/Projects/DIGIMANAGER/venv/lib/python3.13/site-packages/django/views/decorators/http.py", line 64, in inner
    return func(request, *args, **kwargs)
  File "/home/s1gm9/Documents/Projects/DIGIMANAGER/venv/lib/python3.13/site-packages/django/views/decorators/csrf.py", line 65, in _view_wrapper
    return view_func(request, *args, **kwargs)
  File "/home/s1gm9/Documents/Projects/DIGIMANAGER/DIGIMANAGER/scheduler/views.py", line 42, in generate_ai_image
    from yourapp.utils import generate_image_sd  # or your AI image generation logic
    ^^^^^^^^^^^^^^^^^^^^^^^^^^^^^^^^^^^^^^^^^^^
ModuleNotFoundError: No module named 'yourapp'
"POST /ai/generate/1/ HTTP/1.1" 500 76665
Internal Server Error: /ai/generate/1/
Traceback (most recent call last):
  File "/home/s1gm9/Documents/Projects/DIGIMANAGER/venv/lib/python3.13/site-packages/django/core/handlers/exception.py", line 55, in inner
    response = get_response(request)
  File "/home/s1gm9/Documents/Projects/DIGIMANAGER/venv/lib/python3.13/site-packages/django/core/handlers/base.py", line 197, in _get_response
    response = wrapped_callback(request, *callback_args, **callback_kwargs)
  File "/home/s1gm9/Documents/Projects/DIGIMANAGER/venv/lib/python3.13/site-packages/django/views/decorators/http.py", line 64, in inner
    return func(request, *args, **kwargs)
  File "/home/s1gm9/Documents/Projects/DIGIMANAGER/venv/lib/python3.13/site-packages/django/views/decorators/csrf.py", line 65, in _view_wrapper
    return view_func(request, *args, **kwargs)
  File "/home/s1gm9/Documents/Projects/DIGIMANAGER/DIGIMANAGER/scheduler/views.py", line 42, in generate_ai_image
    from yourapp.utils import generate_image_sd  # or your AI image generation logic
    ^^^^^^^^^^^^^^^^^^^^^^^^^^^^^^^^^^^^^^^^^^^
ModuleNotFoundError: No module named 'yourapp'
"POST /ai/generate/1/ HTTP/1.1" 500 76665
Internal Server Error: /ai/generate/1/
Traceback (most recent call last):
  File "/home/s1gm9/Documents/Projects/DIGIMANAGER/venv/lib/python3.13/site-packages/django/core/handlers/exception.py", line 55, in inner
    response = get_response(request)
  File "/home/s1gm9/Documents/Projects/DIGIMANAGER/venv/lib/python3.13/site-packages/django/core/handlers/base.py", line 197, in _get_response
    response = wrapped_callback(request, *callback_args, **callback_kwargs)
  File "/home/s1gm9/Documents/Projects/DIGIMANAGER/venv/lib/python3.13/site-packages/django/views/decorators/http.py", line 64, in inner
    return func(request, *args, **kwargs)
  File "/home/s1gm9/Documents/Projects/DIGIMANAGER/venv/lib/python3.13/site-packages/django/views/decorators/csrf.py", line 65, in _view_wrapper
    return view_func(request, *args, **kwargs)
  File "/home/s1gm9/Documents/Projects/DIGIMANAGER/DIGIMANAGER/scheduler/views.py", line 42, in generate_ai_image
    from yourapp.utils import generate_image_sd  # or your AI image generation logic
    ^^^^^^^^^^^^^^^^^^^^^^^^^^^^^^^^^^^^^^^^^^^
ModuleNotFoundError: No module named 'yourapp'
"POST /ai/generate/1/ HTTP/1.1" 500 76655
Internal Server Error: /ai/generate/1/
Traceback (most recent call last):
  File "/home/s1gm9/Documents/Projects/DIGIMANAGER/venv/lib/python3.13/site-packages/django/core/handlers/exception.py", line 55, in inner
    response = get_response(request)
  File "/home/s1gm9/Documents/Projects/DIGIMANAGER/venv/lib/python3.13/site-packages/django/core/handlers/base.py", line 197, in _get_response
    response = wrapped_callback(request, *callback_args, **callback_kwargs)
  File "/home/s1gm9/Documents/Projects/DIGIMANAGER/venv/lib/python3.13/site-packages/django/views/decorators/http.py", line 64, in inner
    return func(request, *args, **kwargs)
  File "/home/s1gm9/Documents/Projects/DIGIMANAGER/venv/lib/python3.13/site-packages/django/views/decorators/csrf.py", line 65, in _view_wrapper
    return view_func(request, *args, **kwargs)
  File "/home/s1gm9/Documents/Projects/DIGIMANAGER/DIGIMANAGER/scheduler/views.py", line 42, in generate_ai_image
    from yourapp.utils import generate_image_sd  # or your AI image generation logic
    ^^^^^^^^^^^^^^^^^^^^^^^^^^^^^^^^^^^^^^^^^^^
ModuleNotFoundError: No module named 'yourapp'
"POST /ai/generate/1/ HTTP/1.1" 500 76656
Internal Server Error: /posts/create/
Traceback (most recent call last):
  File "/home/s1gm9/Documents/Projects/DIGIMANAGER/venv/lib/python3.13/site-packages/django/core/handlers/exception.py", line 55, in inner
    response = get_response(request)
  File "/home/s1gm9/Documents/Projects/DIGIMANAGER/venv/lib/python3.13/site-packages/django/core/handlers/base.py", line 197, in _get_response
    response = wrapped_callback(request, *callback_args, **callback_kwargs)
  File "/home/s1gm9/Documents/Projects/DIGIMANAGER/venv/lib/python3.13/site-packages/django/contrib/auth/decorators.py", line 60, in _view_wrapper
    return view_func(request, *args, **kwargs)
  File "/home/s1gm9/Documents/Projects/DIGIMANAGER/DIGIMANAGER/scheduler/views.py", line 207, in createPost
    return render(request, 'posts/createPost.html', {'form': form, 'post':post})
                                                                          ^^^^
UnboundLocalError: cannot access local variable 'post' where it is not associated with a value
"GET /posts/create/ HTTP/1.1" 500 73705
Internal Server Error: /posts/create/
Traceback (most recent call last):
  File "/home/s1gm9/Documents/Projects/DIGIMANAGER/venv/lib/python3.13/site-packages/django/core/handlers/exception.py", line 55, in inner
    response = get_response(request)
  File "/home/s1gm9/Documents/Projects/DIGIMANAGER/venv/lib/python3.13/site-packages/django/core/handlers/base.py", line 197, in _get_response
    response = wrapped_callback(request, *callback_args, **callback_kwargs)
  File "/home/s1gm9/Documents/Projects/DIGIMANAGER/venv/lib/python3.13/site-packages/django/contrib/auth/decorators.py", line 60, in _view_wrapper
    return view_func(request, *args, **kwargs)
  File "/home/s1gm9/Documents/Projects/DIGIMANAGER/DIGIMANAGER/scheduler/views.py", line 207, in createPost
    return render(request, 'posts/createPost.html', {'form': form, 'post':post})
                                                                          ^^^^
UnboundLocalError: cannot access local variable 'post' where it is not associated with a value
"GET /posts/create/ HTTP/1.1" 500 73536
Internal Server Error: /posts/create/
Traceback (most recent call last):
  File "/home/s1gm9/Documents/Projects/DIGIMANAGER/venv/lib/python3.13/site-packages/django/core/handlers/exception.py", line 55, in inner
    response = get_response(request)
  File "/home/s1gm9/Documents/Projects/DIGIMANAGER/venv/lib/python3.13/site-packages/django/core/handlers/base.py", line 197, in _get_response
    response = wrapped_callback(request, *callback_args, **callback_kwargs)
  File "/home/s1gm9/Documents/Projects/DIGIMANAGER/venv/lib/python3.13/site-packages/django/contrib/auth/decorators.py", line 60, in _view_wrapper
    return view_func(request, *args, **kwargs)
  File "/home/s1gm9/Documents/Projects/DIGIMANAGER/DIGIMANAGER/scheduler/views.py", line 207, in createPost
    return render(request, 'posts/createPost.html', {'form': form, 'post':post})
                                                                          ^^^^
UnboundLocalError: cannot access local variable 'post' where it is not associated with a value
"GET /posts/create/ HTTP/1.1" 500 73536
Internal Server Error: /posts/create/
Traceback (most recent call last):
  File "/home/s1gm9/Documents/Projects/DIGIMANAGER/venv/lib/python3.13/site-packages/django/core/handlers/exception.py", line 55, in inner
    response = get_response(request)
  File "/home/s1gm9/Documents/Projects/DIGIMANAGER/venv/lib/python3.13/site-packages/django/core/handlers/base.py", line 197, in _get_response
    response = wrapped_callback(request, *callback_args, **callback_kwargs)
  File "/home/s1gm9/Documents/Projects/DIGIMANAGER/venv/lib/python3.13/site-packages/django/contrib/auth/decorators.py", line 60, in _view_wrapper
    return view_func(request, *args, **kwargs)
  File "/home/s1gm9/Documents/Projects/DIGIMANAGER/DIGIMANAGER/scheduler/views.py", line 207, in createPost
    return render(request, 'posts/createPost.html', {'form': form, 'post':post})
                                                                          ^^^^
UnboundLocalError: cannot access local variable 'post' where it is not associated with a value
"GET /posts/create/ HTTP/1.1" 500 73536
Internal Server Error: /posts/create/
Traceback (most recent call last):
  File "/home/s1gm9/Documents/Projects/DIGIMANAGER/venv/lib/python3.13/site-packages/django/core/handlers/exception.py", line 55, in inner
    response = get_response(request)
  File "/home/s1gm9/Documents/Projects/DIGIMANAGER/venv/lib/python3.13/site-packages/django/core/handlers/base.py", line 197, in _get_response
    response = wrapped_callback(request, *callback_args, **callback_kwargs)
  File "/home/s1gm9/Documents/Projects/DIGIMANAGER/venv/lib/python3.13/site-packages/django/contrib/auth/decorators.py", line 60, in _view_wrapper
    return view_func(request, *args, **kwargs)
  File "/home/s1gm9/Documents/Projects/DIGIMANAGER/DIGIMANAGER/scheduler/views.py", line 207, in createPost
    return render(request, 'posts/createPost.html', {'form': form, 'post':post})
                                                                          ^^^^
UnboundLocalError: cannot access local variable 'post' where it is not associated with a value
"GET /posts/create/ HTTP/1.1" 500 73536
Internal Server Error: /posts/create/
Traceback (most recent call last):
  File "/home/s1gm9/Documents/Projects/DIGIMANAGER/venv/lib/python3.13/site-packages/django/core/handlers/exception.py", line 55, in inner
    response = get_response(request)
  File "/home/s1gm9/Documents/Projects/DIGIMANAGER/venv/lib/python3.13/site-packages/django/core/handlers/base.py", line 197, in _get_response
    response = wrapped_callback(request, *callback_args, **callback_kwargs)
  File "/home/s1gm9/Documents/Projects/DIGIMANAGER/venv/lib/python3.13/site-packages/django/contrib/auth/decorators.py", line 60, in _view_wrapper
    return view_func(request, *args, **kwargs)
  File "/home/s1gm9/Documents/Projects/DIGIMANAGER/DIGIMANAGER/scheduler/views.py", line 207, in createPost
    return render(request, 'posts/createPost.html', {'form': form, 'post':post})
                                                                          ^^^^
UnboundLocalError: cannot access local variable 'post' where it is not associated with a value
"GET /posts/create/ HTTP/1.1" 500 73536
Internal Server Error: /posts/create/
Traceback (most recent call last):
  File "/home/s1gm9/Documents/Projects/DIGIMANAGER/venv/lib/python3.13/site-packages/django/core/handlers/exception.py", line 55, in inner
    response = get_response(request)
  File "/home/s1gm9/Documents/Projects/DIGIMANAGER/venv/lib/python3.13/site-packages/django/core/handlers/base.py", line 197, in _get_response
    response = wrapped_callback(request, *callback_args, **callback_kwargs)
  File "/home/s1gm9/Documents/Projects/DIGIMANAGER/venv/lib/python3.13/site-packages/django/contrib/auth/decorators.py", line 60, in _view_wrapper
    return view_func(request, *args, **kwargs)
  File "/home/s1gm9/Documents/Projects/DIGIMANAGER/DIGIMANAGER/scheduler/views.py", line 207, in createPost
    return render(request, 'posts/createPost.html', {'form': form, 'post':post})
                                                                          ^^^^
UnboundLocalError: cannot access local variable 'post' where it is not associated with a value
"GET /posts/create/ HTTP/1.1" 500 73536
Internal Server Error: /posts/create/
Traceback (most recent call last):
  File "/home/s1gm9/Documents/Projects/DIGIMANAGER/venv/lib/python3.13/site-packages/django/core/handlers/exception.py", line 55, in inner
    response = get_response(request)
  File "/home/s1gm9/Documents/Projects/DIGIMANAGER/venv/lib/python3.13/site-packages/django/core/handlers/base.py", line 197, in _get_response
    response = wrapped_callback(request, *callback_args, **callback_kwargs)
  File "/home/s1gm9/Documents/Projects/DIGIMANAGER/venv/lib/python3.13/site-packages/django/contrib/auth/decorators.py", line 60, in _view_wrapper
    return view_func(request, *args, **kwargs)
  File "/home/s1gm9/Documents/Projects/DIGIMANAGER/DIGIMANAGER/scheduler/views.py", line 207, in createPost
    return render(request, 'posts/createPost.html',{'form': form})
  File "/home/s1gm9/Documents/Projects/DIGIMANAGER/venv/lib/python3.13/site-packages/django/shortcuts.py", line 25, in render
    content = loader.render_to_string(template_name, context, request, using=using)
  File "/home/s1gm9/Documents/Projects/DIGIMANAGER/venv/lib/python3.13/site-packages/django/template/loader.py", line 62, in render_to_string
    return template.render(context, request)
           ~~~~~~~~~~~~~~~^^^^^^^^^^^^^^^^^^
  File "/home/s1gm9/Documents/Projects/DIGIMANAGER/venv/lib/python3.13/site-packages/django/template/backends/django.py", line 107, in render
    return self.template.render(context)
           ~~~~~~~~~~~~~~~~~~~~^^^^^^^^^
  File "/home/s1gm9/Documents/Projects/DIGIMANAGER/venv/lib/python3.13/site-packages/django/template/base.py", line 171, in render
    return self._render(context)
           ~~~~~~~~~~~~^^^^^^^^^
  File "/home/s1gm9/Documents/Projects/DIGIMANAGER/venv/lib/python3.13/site-packages/django/template/base.py", line 163, in _render
    return self.nodelist.render(context)
           ~~~~~~~~~~~~~~~~~~~~^^^^^^^^^
  File "/home/s1gm9/Documents/Projects/DIGIMANAGER/venv/lib/python3.13/site-packages/django/template/base.py", line 1008, in render
    return SafeString("".join([node.render_annotated(context) for node in self]))
                               ~~~~~~~~~~~~~~~~~~~~~^^^^^^^^^
  File "/home/s1gm9/Documents/Projects/DIGIMANAGER/venv/lib/python3.13/site-packages/django/template/base.py", line 969, in render_annotated
    return self.render(context)
           ~~~~~~~~~~~^^^^^^^^^
  File "/home/s1gm9/Documents/Projects/DIGIMANAGER/venv/lib/python3.13/site-packages/django/template/loader_tags.py", line 159, in render
    return compiled_parent._render(context)
           ~~~~~~~~~~~~~~~~~~~~~~~^^^^^^^^^
  File "/home/s1gm9/Documents/Projects/DIGIMANAGER/venv/lib/python3.13/site-packages/django/template/base.py", line 163, in _render
    return self.nodelist.render(context)
           ~~~~~~~~~~~~~~~~~~~~^^^^^^^^^
  File "/home/s1gm9/Documents/Projects/DIGIMANAGER/venv/lib/python3.13/site-packages/django/template/base.py", line 1008, in render
    return SafeString("".join([node.render_annotated(context) for node in self]))
                               ~~~~~~~~~~~~~~~~~~~~~^^^^^^^^^
  File "/home/s1gm9/Documents/Projects/DIGIMANAGER/venv/lib/python3.13/site-packages/django/template/base.py", line 969, in render_annotated
    return self.render(context)
           ~~~~~~~~~~~^^^^^^^^^
  File "/home/s1gm9/Documents/Projects/DIGIMANAGER/venv/lib/python3.13/site-packages/django/template/loader_tags.py", line 65, in render
    result = block.nodelist.render(context)
  File "/home/s1gm9/Documents/Projects/DIGIMANAGER/venv/lib/python3.13/site-packages/django/template/base.py", line 1008, in render
    return SafeString("".join([node.render_annotated(context) for node in self]))
                               ~~~~~~~~~~~~~~~~~~~~~^^^^^^^^^
  File "/home/s1gm9/Documents/Projects/DIGIMANAGER/venv/lib/python3.13/site-packages/django/template/base.py", line 969, in render_annotated
    return self.render(context)
           ~~~~~~~~~~~^^^^^^^^^
  File "/home/s1gm9/Documents/Projects/DIGIMANAGER/venv/lib/python3.13/site-packages/django/template/defaulttags.py", line 480, in render
    url = reverse(view_name, args=args, kwargs=kwargs, current_app=current_app)
  File "/home/s1gm9/Documents/Projects/DIGIMANAGER/venv/lib/python3.13/site-packages/django/urls/base.py", line 88, in reverse
    return resolver._reverse_with_prefix(view, prefix, *args, **kwargs)
           ~~~~~~~~~~~~~~~~~~~~~~~~~~~~~^^^^^^^^^^^^^^^^^^^^^^^^^^^^^^^
  File "/home/s1gm9/Documents/Projects/DIGIMANAGER/venv/lib/python3.13/site-packages/django/urls/resolvers.py", line 831, in _reverse_with_prefix
    raise NoReverseMatch(msg)
django.urls.exceptions.NoReverseMatch: Reverse for 'generate_ai_image' with no arguments not found. 1 pattern(s) tried: ['ai/generate/(?P<post_id>[0-9]+)/\\Z']
"GET /posts/create/ HTTP/1.1" 500 160848
Internal Server Error: /ai/generate/
Traceback (most recent call last):
  File "/home/s1gm9/Documents/Projects/DIGIMANAGER/venv/lib/python3.13/site-packages/django/core/handlers/exception.py", line 55, in inner
    response = get_response(request)
  File "/home/s1gm9/Documents/Projects/DIGIMANAGER/venv/lib/python3.13/site-packages/django/core/handlers/base.py", line 197, in _get_response
    response = wrapped_callback(request, *callback_args, **callback_kwargs)
  File "/home/s1gm9/Documents/Projects/DIGIMANAGER/venv/lib/python3.13/site-packages/django/views/decorators/http.py", line 64, in inner
    return func(request, *args, **kwargs)
  File "/home/s1gm9/Documents/Projects/DIGIMANAGER/venv/lib/python3.13/site-packages/django/views/decorators/csrf.py", line 65, in _view_wrapper
    return view_func(request, *args, **kwargs)
TypeError: generate_ai_image() missing 1 required positional argument: 'post_id'
"POST /ai/generate/ HTTP/1.1" 500 73100
Internal Server Error: /ai/generate/
"POST /ai/generate/ HTTP/1.1" 500 37
Internal Server Error: /ai/generate/
"POST /ai/generate/ HTTP/1.1" 500 37
Internal Server Error: /ai/generate/
"POST /ai/generate/ HTTP/1.1" 500 37
Internal Server Error: /ai/generate/
"POST /ai/generate/ HTTP/1.1" 500 37
Internal Server Error: /creator-dashboard/
Traceback (most recent call last):
  File "/home/s1gm9/Documents/Projects/DIGIMANAGER/venv/lib/python3.13/site-packages/django/core/handlers/exception.py", line 55, in inner
    response = get_response(request)
  File "/home/s1gm9/Documents/Projects/DIGIMANAGER/venv/lib/python3.13/site-packages/django/core/handlers/base.py", line 197, in _get_response
    response = wrapped_callback(request, *callback_args, **callback_kwargs)
  File "/home/s1gm9/Documents/Projects/DIGIMANAGER/venv/lib/python3.13/site-packages/django/contrib/auth/decorators.py", line 60, in _view_wrapper
    return view_func(request, *args, **kwargs)
  File "/home/s1gm9/Documents/Projects/DIGIMANAGER/DIGIMANAGER/scheduler/views.py", line 422, in creatorDashboard
    return render(request, 'dashboards/creatorDashboard.html', {
        'posts': my_posts,
        'platforms': platforms,
    })
  File "/home/s1gm9/Documents/Projects/DIGIMANAGER/venv/lib/python3.13/site-packages/django/shortcuts.py", line 25, in render
    content = loader.render_to_string(template_name, context, request, using=using)
  File "/home/s1gm9/Documents/Projects/DIGIMANAGER/venv/lib/python3.13/site-packages/django/template/loader.py", line 62, in render_to_string
    return template.render(context, request)
           ~~~~~~~~~~~~~~~^^^^^^^^^^^^^^^^^^
  File "/home/s1gm9/Documents/Projects/DIGIMANAGER/venv/lib/python3.13/site-packages/django/template/backends/django.py", line 107, in render
    return self.template.render(context)
           ~~~~~~~~~~~~~~~~~~~~^^^^^^^^^
  File "/home/s1gm9/Documents/Projects/DIGIMANAGER/venv/lib/python3.13/site-packages/django/template/base.py", line 171, in render
    return self._render(context)
           ~~~~~~~~~~~~^^^^^^^^^
  File "/home/s1gm9/Documents/Projects/DIGIMANAGER/venv/lib/python3.13/site-packages/django/template/base.py", line 163, in _render
    return self.nodelist.render(context)
           ~~~~~~~~~~~~~~~~~~~~^^^^^^^^^
  File "/home/s1gm9/Documents/Projects/DIGIMANAGER/venv/lib/python3.13/site-packages/django/template/base.py", line 1008, in render
    return SafeString("".join([node.render_annotated(context) for node in self]))
                               ~~~~~~~~~~~~~~~~~~~~~^^^^^^^^^
  File "/home/s1gm9/Documents/Projects/DIGIMANAGER/venv/lib/python3.13/site-packages/django/template/base.py", line 969, in render_annotated
    return self.render(context)
           ~~~~~~~~~~~^^^^^^^^^
  File "/home/s1gm9/Documents/Projects/DIGIMANAGER/venv/lib/python3.13/site-packages/django/template/loader_tags.py", line 159, in render
    return compiled_parent._render(context)
           ~~~~~~~~~~~~~~~~~~~~~~~^^^^^^^^^
  File "/home/s1gm9/Documents/Projects/DIGIMANAGER/venv/lib/python3.13/site-packages/django/template/base.py", line 163, in _render
    return self.nodelist.render(context)
           ~~~~~~~~~~~~~~~~~~~~^^^^^^^^^
  File "/home/s1gm9/Documents/Projects/DIGIMANAGER/venv/lib/python3.13/site-packages/django/template/base.py", line 1008, in render
    return SafeString("".join([node.render_annotated(context) for node in self]))
                               ~~~~~~~~~~~~~~~~~~~~~^^^^^^^^^
  File "/home/s1gm9/Documents/Projects/DIGIMANAGER/venv/lib/python3.13/site-packages/django/template/base.py", line 969, in render_annotated
    return self.render(context)
           ~~~~~~~~~~~^^^^^^^^^
  File "/home/s1gm9/Documents/Projects/DIGIMANAGER/venv/lib/python3.13/site-packages/django/template/loader_tags.py", line 65, in render
    result = block.nodelist.render(context)
  File "/home/s1gm9/Documents/Projects/DIGIMANAGER/venv/lib/python3.13/site-packages/django/template/base.py", line 1008, in render
    return SafeString("".join([node.render_annotated(context) for node in self]))
                               ~~~~~~~~~~~~~~~~~~~~~^^^^^^^^^
  File "/home/s1gm9/Documents/Projects/DIGIMANAGER/venv/lib/python3.13/site-packages/django/template/base.py", line 969, in render_annotated
    return self.render(context)
           ~~~~~~~~~~~^^^^^^^^^
  File "/home/s1gm9/Documents/Projects/DIGIMANAGER/venv/lib/python3.13/site-packages/django/template/defaulttags.py", line 327, in render
    return nodelist.render(context)
           ~~~~~~~~~~~~~~~^^^^^^^^^
  File "/home/s1gm9/Documents/Projects/DIGIMANAGER/venv/lib/python3.13/site-packages/django/template/base.py", line 1008, in render
    return SafeString("".join([node.render_annotated(context) for node in self]))
                               ~~~~~~~~~~~~~~~~~~~~~^^^^^^^^^
  File "/home/s1gm9/Documents/Projects/DIGIMANAGER/venv/lib/python3.13/site-packages/django/template/base.py", line 969, in render_annotated
    return self.render(context)
           ~~~~~~~~~~~^^^^^^^^^
  File "/home/s1gm9/Documents/Projects/DIGIMANAGER/venv/lib/python3.13/site-packages/django/template/defaulttags.py", line 243, in render
    nodelist.append(node.render_annotated(context))
                    ~~~~~~~~~~~~~~~~~~~~~^^^^^^^^^
  File "/home/s1gm9/Documents/Projects/DIGIMANAGER/venv/lib/python3.13/site-packages/django/template/base.py", line 969, in render_annotated
    return self.render(context)
           ~~~~~~~~~~~^^^^^^^^^
  File "/home/s1gm9/Documents/Projects/DIGIMANAGER/venv/lib/python3.13/site-packages/django/template/defaulttags.py", line 480, in render
    url = reverse(view_name, args=args, kwargs=kwargs, current_app=current_app)
  File "/home/s1gm9/Documents/Projects/DIGIMANAGER/venv/lib/python3.13/site-packages/django/urls/base.py", line 88, in reverse
    return resolver._reverse_with_prefix(view, prefix, *args, **kwargs)
           ~~~~~~~~~~~~~~~~~~~~~~~~~~~~~^^^^^^^^^^^^^^^^^^^^^^^^^^^^^^^
  File "/home/s1gm9/Documents/Projects/DIGIMANAGER/venv/lib/python3.13/site-packages/django/urls/resolvers.py", line 831, in _reverse_with_prefix
    raise NoReverseMatch(msg)
django.urls.exceptions.NoReverseMatch: Reverse for 'viewPost' with arguments '(1,)' not found. 1 pattern(s) tried: ['posts/view/\\Z']
"GET /creator-dashboard/ HTTP/1.1" 500 191072
Internal Server Error: /creator-dashboard/
Traceback (most recent call last):
  File "/home/s1gm9/Documents/Projects/DIGIMANAGER/venv/lib/python3.13/site-packages/django/core/handlers/exception.py", line 55, in inner
    response = get_response(request)
  File "/home/s1gm9/Documents/Projects/DIGIMANAGER/venv/lib/python3.13/site-packages/django/core/handlers/base.py", line 197, in _get_response
    response = wrapped_callback(request, *callback_args, **callback_kwargs)
  File "/home/s1gm9/Documents/Projects/DIGIMANAGER/venv/lib/python3.13/site-packages/django/contrib/auth/decorators.py", line 60, in _view_wrapper
    return view_func(request, *args, **kwargs)
  File "/home/s1gm9/Documents/Projects/DIGIMANAGER/DIGIMANAGER/scheduler/views.py", line 422, in creatorDashboard
    return render(request, 'dashboards/creatorDashboard.html', {
        'posts': my_posts,
        'platforms': platforms,
    })
  File "/home/s1gm9/Documents/Projects/DIGIMANAGER/venv/lib/python3.13/site-packages/django/shortcuts.py", line 25, in render
    content = loader.render_to_string(template_name, context, request, using=using)
  File "/home/s1gm9/Documents/Projects/DIGIMANAGER/venv/lib/python3.13/site-packages/django/template/loader.py", line 62, in render_to_string
    return template.render(context, request)
           ~~~~~~~~~~~~~~~^^^^^^^^^^^^^^^^^^
  File "/home/s1gm9/Documents/Projects/DIGIMANAGER/venv/lib/python3.13/site-packages/django/template/backends/django.py", line 107, in render
    return self.template.render(context)
           ~~~~~~~~~~~~~~~~~~~~^^^^^^^^^
  File "/home/s1gm9/Documents/Projects/DIGIMANAGER/venv/lib/python3.13/site-packages/django/template/base.py", line 171, in render
    return self._render(context)
           ~~~~~~~~~~~~^^^^^^^^^
  File "/home/s1gm9/Documents/Projects/DIGIMANAGER/venv/lib/python3.13/site-packages/django/template/base.py", line 163, in _render
    return self.nodelist.render(context)
           ~~~~~~~~~~~~~~~~~~~~^^^^^^^^^
  File "/home/s1gm9/Documents/Projects/DIGIMANAGER/venv/lib/python3.13/site-packages/django/template/base.py", line 1008, in render
    return SafeString("".join([node.render_annotated(context) for node in self]))
                               ~~~~~~~~~~~~~~~~~~~~~^^^^^^^^^
  File "/home/s1gm9/Documents/Projects/DIGIMANAGER/venv/lib/python3.13/site-packages/django/template/base.py", line 969, in render_annotated
    return self.render(context)
           ~~~~~~~~~~~^^^^^^^^^
  File "/home/s1gm9/Documents/Projects/DIGIMANAGER/venv/lib/python3.13/site-packages/django/template/loader_tags.py", line 159, in render
    return compiled_parent._render(context)
           ~~~~~~~~~~~~~~~~~~~~~~~^^^^^^^^^
  File "/home/s1gm9/Documents/Projects/DIGIMANAGER/venv/lib/python3.13/site-packages/django/template/base.py", line 163, in _render
    return self.nodelist.render(context)
           ~~~~~~~~~~~~~~~~~~~~^^^^^^^^^
  File "/home/s1gm9/Documents/Projects/DIGIMANAGER/venv/lib/python3.13/site-packages/django/template/base.py", line 1008, in render
    return SafeString("".join([node.render_annotated(context) for node in self]))
                               ~~~~~~~~~~~~~~~~~~~~~^^^^^^^^^
  File "/home/s1gm9/Documents/Projects/DIGIMANAGER/venv/lib/python3.13/site-packages/django/template/base.py", line 969, in render_annotated
    return self.render(context)
           ~~~~~~~~~~~^^^^^^^^^
  File "/home/s1gm9/Documents/Projects/DIGIMANAGER/venv/lib/python3.13/site-packages/django/template/loader_tags.py", line 65, in render
    result = block.nodelist.render(context)
  File "/home/s1gm9/Documents/Projects/DIGIMANAGER/venv/lib/python3.13/site-packages/django/template/base.py", line 1008, in render
    return SafeString("".join([node.render_annotated(context) for node in self]))
                               ~~~~~~~~~~~~~~~~~~~~~^^^^^^^^^
  File "/home/s1gm9/Documents/Projects/DIGIMANAGER/venv/lib/python3.13/site-packages/django/template/base.py", line 969, in render_annotated
    return self.render(context)
           ~~~~~~~~~~~^^^^^^^^^
  File "/home/s1gm9/Documents/Projects/DIGIMANAGER/venv/lib/python3.13/site-packages/django/template/defaulttags.py", line 327, in render
    return nodelist.render(context)
           ~~~~~~~~~~~~~~~^^^^^^^^^
  File "/home/s1gm9/Documents/Projects/DIGIMANAGER/venv/lib/python3.13/site-packages/django/template/base.py", line 1008, in render
    return SafeString("".join([node.render_annotated(context) for node in self]))
                               ~~~~~~~~~~~~~~~~~~~~~^^^^^^^^^
  File "/home/s1gm9/Documents/Projects/DIGIMANAGER/venv/lib/python3.13/site-packages/django/template/base.py", line 969, in render_annotated
    return self.render(context)
           ~~~~~~~~~~~^^^^^^^^^
  File "/home/s1gm9/Documents/Projects/DIGIMANAGER/venv/lib/python3.13/site-packages/django/template/defaulttags.py", line 243, in render
    nodelist.append(node.render_annotated(context))
                    ~~~~~~~~~~~~~~~~~~~~~^^^^^^^^^
  File "/home/s1gm9/Documents/Projects/DIGIMANAGER/venv/lib/python3.13/site-packages/django/template/base.py", line 969, in render_annotated
    return self.render(context)
           ~~~~~~~~~~~^^^^^^^^^
  File "/home/s1gm9/Documents/Projects/DIGIMANAGER/venv/lib/python3.13/site-packages/django/template/defaulttags.py", line 480, in render
    url = reverse(view_name, args=args, kwargs=kwargs, current_app=current_app)
  File "/home/s1gm9/Documents/Projects/DIGIMANAGER/venv/lib/python3.13/site-packages/django/urls/base.py", line 88, in reverse
    return resolver._reverse_with_prefix(view, prefix, *args, **kwargs)
           ~~~~~~~~~~~~~~~~~~~~~~~~~~~~~^^^^^^^^^^^^^^^^^^^^^^^^^^^^^^^
  File "/home/s1gm9/Documents/Projects/DIGIMANAGER/venv/lib/python3.13/site-packages/django/urls/resolvers.py", line 831, in _reverse_with_prefix
    raise NoReverseMatch(msg)
django.urls.exceptions.NoReverseMatch: Reverse for 'viewPost' with arguments '(1,)' not found. 1 pattern(s) tried: ['posts/view/\\Z']
"GET /creator-dashboard/ HTTP/1.1" 500 192017
Internal Server Error: /creator-dashboard/
Traceback (most recent call last):
  File "/home/s1gm9/Documents/Projects/DIGIMANAGER/venv/lib/python3.13/site-packages/django/core/handlers/exception.py", line 55, in inner
    response = get_response(request)
  File "/home/s1gm9/Documents/Projects/DIGIMANAGER/venv/lib/python3.13/site-packages/django/core/handlers/base.py", line 197, in _get_response
    response = wrapped_callback(request, *callback_args, **callback_kwargs)
  File "/home/s1gm9/Documents/Projects/DIGIMANAGER/venv/lib/python3.13/site-packages/django/contrib/auth/decorators.py", line 60, in _view_wrapper
    return view_func(request, *args, **kwargs)
  File "/home/s1gm9/Documents/Projects/DIGIMANAGER/DIGIMANAGER/scheduler/views.py", line 422, in creatorDashboard
    return render(request, 'dashboards/creatorDashboard.html', {
        'posts': my_posts,
        'platforms': platforms,
    })
  File "/home/s1gm9/Documents/Projects/DIGIMANAGER/venv/lib/python3.13/site-packages/django/shortcuts.py", line 25, in render
    content = loader.render_to_string(template_name, context, request, using=using)
  File "/home/s1gm9/Documents/Projects/DIGIMANAGER/venv/lib/python3.13/site-packages/django/template/loader.py", line 62, in render_to_string
    return template.render(context, request)
           ~~~~~~~~~~~~~~~^^^^^^^^^^^^^^^^^^
  File "/home/s1gm9/Documents/Projects/DIGIMANAGER/venv/lib/python3.13/site-packages/django/template/backends/django.py", line 107, in render
    return self.template.render(context)
           ~~~~~~~~~~~~~~~~~~~~^^^^^^^^^
  File "/home/s1gm9/Documents/Projects/DIGIMANAGER/venv/lib/python3.13/site-packages/django/template/base.py", line 171, in render
    return self._render(context)
           ~~~~~~~~~~~~^^^^^^^^^
  File "/home/s1gm9/Documents/Projects/DIGIMANAGER/venv/lib/python3.13/site-packages/django/template/base.py", line 163, in _render
    return self.nodelist.render(context)
           ~~~~~~~~~~~~~~~~~~~~^^^^^^^^^
  File "/home/s1gm9/Documents/Projects/DIGIMANAGER/venv/lib/python3.13/site-packages/django/template/base.py", line 1008, in render
    return SafeString("".join([node.render_annotated(context) for node in self]))
                               ~~~~~~~~~~~~~~~~~~~~~^^^^^^^^^
  File "/home/s1gm9/Documents/Projects/DIGIMANAGER/venv/lib/python3.13/site-packages/django/template/base.py", line 969, in render_annotated
    return self.render(context)
           ~~~~~~~~~~~^^^^^^^^^
  File "/home/s1gm9/Documents/Projects/DIGIMANAGER/venv/lib/python3.13/site-packages/django/template/loader_tags.py", line 159, in render
    return compiled_parent._render(context)
           ~~~~~~~~~~~~~~~~~~~~~~~^^^^^^^^^
  File "/home/s1gm9/Documents/Projects/DIGIMANAGER/venv/lib/python3.13/site-packages/django/template/base.py", line 163, in _render
    return self.nodelist.render(context)
           ~~~~~~~~~~~~~~~~~~~~^^^^^^^^^
  File "/home/s1gm9/Documents/Projects/DIGIMANAGER/venv/lib/python3.13/site-packages/django/template/base.py", line 1008, in render
    return SafeString("".join([node.render_annotated(context) for node in self]))
                               ~~~~~~~~~~~~~~~~~~~~~^^^^^^^^^
  File "/home/s1gm9/Documents/Projects/DIGIMANAGER/venv/lib/python3.13/site-packages/django/template/base.py", line 969, in render_annotated
    return self.render(context)
           ~~~~~~~~~~~^^^^^^^^^
  File "/home/s1gm9/Documents/Projects/DIGIMANAGER/venv/lib/python3.13/site-packages/django/template/loader_tags.py", line 65, in render
    result = block.nodelist.render(context)
  File "/home/s1gm9/Documents/Projects/DIGIMANAGER/venv/lib/python3.13/site-packages/django/template/base.py", line 1008, in render
    return SafeString("".join([node.render_annotated(context) for node in self]))
                               ~~~~~~~~~~~~~~~~~~~~~^^^^^^^^^
  File "/home/s1gm9/Documents/Projects/DIGIMANAGER/venv/lib/python3.13/site-packages/django/template/base.py", line 969, in render_annotated
    return self.render(context)
           ~~~~~~~~~~~^^^^^^^^^
  File "/home/s1gm9/Documents/Projects/DIGIMANAGER/venv/lib/python3.13/site-packages/django/template/defaulttags.py", line 327, in render
    return nodelist.render(context)
           ~~~~~~~~~~~~~~~^^^^^^^^^
  File "/home/s1gm9/Documents/Projects/DIGIMANAGER/venv/lib/python3.13/site-packages/django/template/base.py", line 1008, in render
    return SafeString("".join([node.render_annotated(context) for node in self]))
                               ~~~~~~~~~~~~~~~~~~~~~^^^^^^^^^
  File "/home/s1gm9/Documents/Projects/DIGIMANAGER/venv/lib/python3.13/site-packages/django/template/base.py", line 969, in render_annotated
    return self.render(context)
           ~~~~~~~~~~~^^^^^^^^^
  File "/home/s1gm9/Documents/Projects/DIGIMANAGER/venv/lib/python3.13/site-packages/django/template/defaulttags.py", line 243, in render
    nodelist.append(node.render_annotated(context))
                    ~~~~~~~~~~~~~~~~~~~~~^^^^^^^^^
  File "/home/s1gm9/Documents/Projects/DIGIMANAGER/venv/lib/python3.13/site-packages/django/template/base.py", line 969, in render_annotated
    return self.render(context)
           ~~~~~~~~~~~^^^^^^^^^
  File "/home/s1gm9/Documents/Projects/DIGIMANAGER/venv/lib/python3.13/site-packages/django/template/defaulttags.py", line 480, in render
    url = reverse(view_name, args=args, kwargs=kwargs, current_app=current_app)
  File "/home/s1gm9/Documents/Projects/DIGIMANAGER/venv/lib/python3.13/site-packages/django/urls/base.py", line 88, in reverse
    return resolver._reverse_with_prefix(view, prefix, *args, **kwargs)
           ~~~~~~~~~~~~~~~~~~~~~~~~~~~~~^^^^^^^^^^^^^^^^^^^^^^^^^^^^^^^
  File "/home/s1gm9/Documents/Projects/DIGIMANAGER/venv/lib/python3.13/site-packages/django/urls/resolvers.py", line 831, in _reverse_with_prefix
    raise NoReverseMatch(msg)
django.urls.exceptions.NoReverseMatch: Reverse for 'viewPost' with arguments '(1,)' not found. 1 pattern(s) tried: ['posts/view/\\Z']
"GET /creator-dashboard/ HTTP/1.1" 500 191600
Internal Server Error: /creator-dashboard/
Traceback (most recent call last):
  File "/home/s1gm9/Documents/Projects/DIGIMANAGER/venv/lib/python3.13/site-packages/django/core/handlers/exception.py", line 55, in inner
    response = get_response(request)
  File "/home/s1gm9/Documents/Projects/DIGIMANAGER/venv/lib/python3.13/site-packages/django/core/handlers/base.py", line 197, in _get_response
    response = wrapped_callback(request, *callback_args, **callback_kwargs)
  File "/home/s1gm9/Documents/Projects/DIGIMANAGER/venv/lib/python3.13/site-packages/django/contrib/auth/decorators.py", line 60, in _view_wrapper
    return view_func(request, *args, **kwargs)
  File "/home/s1gm9/Documents/Projects/DIGIMANAGER/DIGIMANAGER/scheduler/views.py", line 422, in creatorDashboard
    return render(request, 'dashboards/creatorDashboard.html', {
        'posts': my_posts,
        'platforms': platforms,
    })
  File "/home/s1gm9/Documents/Projects/DIGIMANAGER/venv/lib/python3.13/site-packages/django/shortcuts.py", line 25, in render
    content = loader.render_to_string(template_name, context, request, using=using)
  File "/home/s1gm9/Documents/Projects/DIGIMANAGER/venv/lib/python3.13/site-packages/django/template/loader.py", line 62, in render_to_string
    return template.render(context, request)
           ~~~~~~~~~~~~~~~^^^^^^^^^^^^^^^^^^
  File "/home/s1gm9/Documents/Projects/DIGIMANAGER/venv/lib/python3.13/site-packages/django/template/backends/django.py", line 107, in render
    return self.template.render(context)
           ~~~~~~~~~~~~~~~~~~~~^^^^^^^^^
  File "/home/s1gm9/Documents/Projects/DIGIMANAGER/venv/lib/python3.13/site-packages/django/template/base.py", line 171, in render
    return self._render(context)
           ~~~~~~~~~~~~^^^^^^^^^
  File "/home/s1gm9/Documents/Projects/DIGIMANAGER/venv/lib/python3.13/site-packages/django/template/base.py", line 163, in _render
    return self.nodelist.render(context)
           ~~~~~~~~~~~~~~~~~~~~^^^^^^^^^
  File "/home/s1gm9/Documents/Projects/DIGIMANAGER/venv/lib/python3.13/site-packages/django/template/base.py", line 1008, in render
    return SafeString("".join([node.render_annotated(context) for node in self]))
                               ~~~~~~~~~~~~~~~~~~~~~^^^^^^^^^
  File "/home/s1gm9/Documents/Projects/DIGIMANAGER/venv/lib/python3.13/site-packages/django/template/base.py", line 969, in render_annotated
    return self.render(context)
           ~~~~~~~~~~~^^^^^^^^^
  File "/home/s1gm9/Documents/Projects/DIGIMANAGER/venv/lib/python3.13/site-packages/django/template/loader_tags.py", line 159, in render
    return compiled_parent._render(context)
           ~~~~~~~~~~~~~~~~~~~~~~~^^^^^^^^^
  File "/home/s1gm9/Documents/Projects/DIGIMANAGER/venv/lib/python3.13/site-packages/django/template/base.py", line 163, in _render
    return self.nodelist.render(context)
           ~~~~~~~~~~~~~~~~~~~~^^^^^^^^^
  File "/home/s1gm9/Documents/Projects/DIGIMANAGER/venv/lib/python3.13/site-packages/django/template/base.py", line 1008, in render
    return SafeString("".join([node.render_annotated(context) for node in self]))
                               ~~~~~~~~~~~~~~~~~~~~~^^^^^^^^^
  File "/home/s1gm9/Documents/Projects/DIGIMANAGER/venv/lib/python3.13/site-packages/django/template/base.py", line 969, in render_annotated
    return self.render(context)
           ~~~~~~~~~~~^^^^^^^^^
  File "/home/s1gm9/Documents/Projects/DIGIMANAGER/venv/lib/python3.13/site-packages/django/template/loader_tags.py", line 65, in render
    result = block.nodelist.render(context)
  File "/home/s1gm9/Documents/Projects/DIGIMANAGER/venv/lib/python3.13/site-packages/django/template/base.py", line 1008, in render
    return SafeString("".join([node.render_annotated(context) for node in self]))
                               ~~~~~~~~~~~~~~~~~~~~~^^^^^^^^^
  File "/home/s1gm9/Documents/Projects/DIGIMANAGER/venv/lib/python3.13/site-packages/django/template/base.py", line 969, in render_annotated
    return self.render(context)
           ~~~~~~~~~~~^^^^^^^^^
  File "/home/s1gm9/Documents/Projects/DIGIMANAGER/venv/lib/python3.13/site-packages/django/template/defaulttags.py", line 327, in render
    return nodelist.render(context)
           ~~~~~~~~~~~~~~~^^^^^^^^^
  File "/home/s1gm9/Documents/Projects/DIGIMANAGER/venv/lib/python3.13/site-packages/django/template/base.py", line 1008, in render
    return SafeString("".join([node.render_annotated(context) for node in self]))
                               ~~~~~~~~~~~~~~~~~~~~~^^^^^^^^^
  File "/home/s1gm9/Documents/Projects/DIGIMANAGER/venv/lib/python3.13/site-packages/django/template/base.py", line 969, in render_annotated
    return self.render(context)
           ~~~~~~~~~~~^^^^^^^^^
  File "/home/s1gm9/Documents/Projects/DIGIMANAGER/venv/lib/python3.13/site-packages/django/template/defaulttags.py", line 243, in render
    nodelist.append(node.render_annotated(context))
                    ~~~~~~~~~~~~~~~~~~~~~^^^^^^^^^
  File "/home/s1gm9/Documents/Projects/DIGIMANAGER/venv/lib/python3.13/site-packages/django/template/base.py", line 969, in render_annotated
    return self.render(context)
           ~~~~~~~~~~~^^^^^^^^^
  File "/home/s1gm9/Documents/Projects/DIGIMANAGER/venv/lib/python3.13/site-packages/django/template/defaulttags.py", line 480, in render
    url = reverse(view_name, args=args, kwargs=kwargs, current_app=current_app)
  File "/home/s1gm9/Documents/Projects/DIGIMANAGER/venv/lib/python3.13/site-packages/django/urls/base.py", line 88, in reverse
    return resolver._reverse_with_prefix(view, prefix, *args, **kwargs)
           ~~~~~~~~~~~~~~~~~~~~~~~~~~~~~^^^^^^^^^^^^^^^^^^^^^^^^^^^^^^^
  File "/home/s1gm9/Documents/Projects/DIGIMANAGER/venv/lib/python3.13/site-packages/django/urls/resolvers.py", line 831, in _reverse_with_prefix
    raise NoReverseMatch(msg)
django.urls.exceptions.NoReverseMatch: Reverse for 'viewPost' with arguments '(1,)' not found. 1 pattern(s) tried: ['posts/view/\\Z']
"GET /creator-dashboard/ HTTP/1.1" 500 191600
Internal Server Error: /creator-dashboard/
Traceback (most recent call last):
  File "/home/s1gm9/Documents/Projects/DIGIMANAGER/venv/lib/python3.13/site-packages/django/core/handlers/exception.py", line 55, in inner
    response = get_response(request)
  File "/home/s1gm9/Documents/Projects/DIGIMANAGER/venv/lib/python3.13/site-packages/django/core/handlers/base.py", line 197, in _get_response
    response = wrapped_callback(request, *callback_args, **callback_kwargs)
  File "/home/s1gm9/Documents/Projects/DIGIMANAGER/venv/lib/python3.13/site-packages/django/contrib/auth/decorators.py", line 60, in _view_wrapper
    return view_func(request, *args, **kwargs)
  File "/home/s1gm9/Documents/Projects/DIGIMANAGER/DIGIMANAGER/scheduler/views.py", line 422, in creatorDashboard
    return render(request, 'dashboards/creatorDashboard.html', {
        'posts': my_posts,
        'platforms': platforms,
    })
  File "/home/s1gm9/Documents/Projects/DIGIMANAGER/venv/lib/python3.13/site-packages/django/shortcuts.py", line 25, in render
    content = loader.render_to_string(template_name, context, request, using=using)
  File "/home/s1gm9/Documents/Projects/DIGIMANAGER/venv/lib/python3.13/site-packages/django/template/loader.py", line 62, in render_to_string
    return template.render(context, request)
           ~~~~~~~~~~~~~~~^^^^^^^^^^^^^^^^^^
  File "/home/s1gm9/Documents/Projects/DIGIMANAGER/venv/lib/python3.13/site-packages/django/template/backends/django.py", line 107, in render
    return self.template.render(context)
           ~~~~~~~~~~~~~~~~~~~~^^^^^^^^^
  File "/home/s1gm9/Documents/Projects/DIGIMANAGER/venv/lib/python3.13/site-packages/django/template/base.py", line 171, in render
    return self._render(context)
           ~~~~~~~~~~~~^^^^^^^^^
  File "/home/s1gm9/Documents/Projects/DIGIMANAGER/venv/lib/python3.13/site-packages/django/template/base.py", line 163, in _render
    return self.nodelist.render(context)
           ~~~~~~~~~~~~~~~~~~~~^^^^^^^^^
  File "/home/s1gm9/Documents/Projects/DIGIMANAGER/venv/lib/python3.13/site-packages/django/template/base.py", line 1008, in render
    return SafeString("".join([node.render_annotated(context) for node in self]))
                               ~~~~~~~~~~~~~~~~~~~~~^^^^^^^^^
  File "/home/s1gm9/Documents/Projects/DIGIMANAGER/venv/lib/python3.13/site-packages/django/template/base.py", line 969, in render_annotated
    return self.render(context)
           ~~~~~~~~~~~^^^^^^^^^
  File "/home/s1gm9/Documents/Projects/DIGIMANAGER/venv/lib/python3.13/site-packages/django/template/loader_tags.py", line 159, in render
    return compiled_parent._render(context)
           ~~~~~~~~~~~~~~~~~~~~~~~^^^^^^^^^
  File "/home/s1gm9/Documents/Projects/DIGIMANAGER/venv/lib/python3.13/site-packages/django/template/base.py", line 163, in _render
    return self.nodelist.render(context)
           ~~~~~~~~~~~~~~~~~~~~^^^^^^^^^
  File "/home/s1gm9/Documents/Projects/DIGIMANAGER/venv/lib/python3.13/site-packages/django/template/base.py", line 1008, in render
    return SafeString("".join([node.render_annotated(context) for node in self]))
                               ~~~~~~~~~~~~~~~~~~~~~^^^^^^^^^
  File "/home/s1gm9/Documents/Projects/DIGIMANAGER/venv/lib/python3.13/site-packages/django/template/base.py", line 969, in render_annotated
    return self.render(context)
           ~~~~~~~~~~~^^^^^^^^^
  File "/home/s1gm9/Documents/Projects/DIGIMANAGER/venv/lib/python3.13/site-packages/django/template/loader_tags.py", line 65, in render
    result = block.nodelist.render(context)
  File "/home/s1gm9/Documents/Projects/DIGIMANAGER/venv/lib/python3.13/site-packages/django/template/base.py", line 1008, in render
    return SafeString("".join([node.render_annotated(context) for node in self]))
                               ~~~~~~~~~~~~~~~~~~~~~^^^^^^^^^
  File "/home/s1gm9/Documents/Projects/DIGIMANAGER/venv/lib/python3.13/site-packages/django/template/base.py", line 969, in render_annotated
    return self.render(context)
           ~~~~~~~~~~~^^^^^^^^^
  File "/home/s1gm9/Documents/Projects/DIGIMANAGER/venv/lib/python3.13/site-packages/django/template/defaulttags.py", line 327, in render
    return nodelist.render(context)
           ~~~~~~~~~~~~~~~^^^^^^^^^
  File "/home/s1gm9/Documents/Projects/DIGIMANAGER/venv/lib/python3.13/site-packages/django/template/base.py", line 1008, in render
    return SafeString("".join([node.render_annotated(context) for node in self]))
                               ~~~~~~~~~~~~~~~~~~~~~^^^^^^^^^
  File "/home/s1gm9/Documents/Projects/DIGIMANAGER/venv/lib/python3.13/site-packages/django/template/base.py", line 969, in render_annotated
    return self.render(context)
           ~~~~~~~~~~~^^^^^^^^^
  File "/home/s1gm9/Documents/Projects/DIGIMANAGER/venv/lib/python3.13/site-packages/django/template/defaulttags.py", line 243, in render
    nodelist.append(node.render_annotated(context))
                    ~~~~~~~~~~~~~~~~~~~~~^^^^^^^^^
  File "/home/s1gm9/Documents/Projects/DIGIMANAGER/venv/lib/python3.13/site-packages/django/template/base.py", line 969, in render_annotated
    return self.render(context)
           ~~~~~~~~~~~^^^^^^^^^
  File "/home/s1gm9/Documents/Projects/DIGIMANAGER/venv/lib/python3.13/site-packages/django/template/defaulttags.py", line 480, in render
    url = reverse(view_name, args=args, kwargs=kwargs, current_app=current_app)
  File "/home/s1gm9/Documents/Projects/DIGIMANAGER/venv/lib/python3.13/site-packages/django/urls/base.py", line 88, in reverse
    return resolver._reverse_with_prefix(view, prefix, *args, **kwargs)
           ~~~~~~~~~~~~~~~~~~~~~~~~~~~~~^^^^^^^^^^^^^^^^^^^^^^^^^^^^^^^
  File "/home/s1gm9/Documents/Projects/DIGIMANAGER/venv/lib/python3.13/site-packages/django/urls/resolvers.py", line 831, in _reverse_with_prefix
    raise NoReverseMatch(msg)
django.urls.exceptions.NoReverseMatch: Reverse for 'deletePost' with arguments '(1,)' not found. 1 pattern(s) tried: ['posts/delete/\\Z']
"GET /creator-dashboard/ HTTP/1.1" 500 191794
Internal Server Error: /post/1/edit/
Traceback (most recent call last):
  File "/home/s1gm9/Documents/Projects/DIGIMANAGER/venv/lib/python3.13/site-packages/django/core/handlers/exception.py", line 55, in inner
    response = get_response(request)
  File "/home/s1gm9/Documents/Projects/DIGIMANAGER/venv/lib/python3.13/site-packages/django/core/handlers/base.py", line 197, in _get_response
    response = wrapped_callback(request, *callback_args, **callback_kwargs)
  File "/home/s1gm9/Documents/Projects/DIGIMANAGER/DIGIMANAGER/scheduler/views.py", line 297, in editPost
    return render(request, 'contentgen/createPost.html', {
        'form': form,
        'post': post,  # pass this for AI previews and JS updates
    })
  File "/home/s1gm9/Documents/Projects/DIGIMANAGER/venv/lib/python3.13/site-packages/django/shortcuts.py", line 25, in render
    content = loader.render_to_string(template_name, context, request, using=using)
  File "/home/s1gm9/Documents/Projects/DIGIMANAGER/venv/lib/python3.13/site-packages/django/template/loader.py", line 61, in render_to_string
    template = get_template(template_name, using=using)
  File "/home/s1gm9/Documents/Projects/DIGIMANAGER/venv/lib/python3.13/site-packages/django/template/loader.py", line 19, in get_template
    raise TemplateDoesNotExist(template_name, chain=chain)
django.template.exceptions.TemplateDoesNotExist: contentgen/createPost.html
"GET /post/1/edit/ HTTP/1.1" 500 84720
Internal Server Error: /post/1/edit/
Traceback (most recent call last):
  File "/home/s1gm9/Documents/Projects/DIGIMANAGER/venv/lib/python3.13/site-packages/django/core/handlers/exception.py", line 55, in inner
    response = get_response(request)
  File "/home/s1gm9/Documents/Projects/DIGIMANAGER/venv/lib/python3.13/site-packages/django/core/handlers/base.py", line 197, in _get_response
    response = wrapped_callback(request, *callback_args, **callback_kwargs)
  File "/home/s1gm9/Documents/Projects/DIGIMANAGER/venv/lib/python3.13/site-packages/django/contrib/auth/decorators.py", line 60, in _view_wrapper
    return view_func(request, *args, **kwargs)
TypeError: editPost() got an unexpected keyword argument 'pk'
"GET /post/1/edit/ HTTP/1.1" 500 69188
Internal Server Error: /post/1/edit/
Traceback (most recent call last):
  File "/home/s1gm9/Documents/Projects/DIGIMANAGER/venv/lib/python3.13/site-packages/django/core/handlers/exception.py", line 55, in inner
    response = get_response(request)
  File "/home/s1gm9/Documents/Projects/DIGIMANAGER/venv/lib/python3.13/site-packages/django/core/handlers/base.py", line 197, in _get_response
    response = wrapped_callback(request, *callback_args, **callback_kwargs)
  File "/home/s1gm9/Documents/Projects/DIGIMANAGER/venv/lib/python3.13/site-packages/django/contrib/auth/decorators.py", line 60, in _view_wrapper
    return view_func(request, *args, **kwargs)
TypeError: editPost() got an unexpected keyword argument 'pk'
"GET /post/1/edit/ HTTP/1.1" 500 69188
Internal Server Error: /post/1/edit/
Traceback (most recent call last):
  File "/home/s1gm9/Documents/Projects/DIGIMANAGER/venv/lib/python3.13/site-packages/django/core/handlers/exception.py", line 55, in inner
    response = get_response(request)
  File "/home/s1gm9/Documents/Projects/DIGIMANAGER/venv/lib/python3.13/site-packages/django/core/handlers/base.py", line 197, in _get_response
    response = wrapped_callback(request, *callback_args, **callback_kwargs)
  File "/home/s1gm9/Documents/Projects/DIGIMANAGER/venv/lib/python3.13/site-packages/django/contrib/auth/decorators.py", line 60, in _view_wrapper
    return view_func(request, *args, **kwargs)
TypeError: editPost() got an unexpected keyword argument 'pk'
"GET /post/1/edit/ HTTP/1.1" 500 69345
