Internal Server Error: /ai/generate/1/
Traceback (most recent call last):
  File "/home/s1gm9/Documents/Projects/DIGIMANAGER/venv/lib/python3.13/site-packages/django/core/handlers/exception.py", line 55, in inner
    response = get_response(request)
  File "/home/s1gm9/Documents/Projects/DIGIMANAGER/venv/lib/python3.13/site-packages/django/core/handlers/base.py", line 197, in _get_response
    response = wrapped_callback(request, *callback_args, **callback_kwargs)
  File "/home/s1gm9/Documents/Projects/DIGIMANAGER/venv/lib/python3.13/site-packages/django/views/decorators/http.py", line 64, in inner
    return func(request, *args, **kwargs)
  File "/home/s1gm9/Documents/Projects/DIGIMANAGER/venv/lib/python3.13/site-packages/django/views/decorators/csrf.py", line 65, in _view_wrapper
    return view_func(request, *args, **kwargs)
  File "/home/s1gm9/Documents/Projects/DIGIMANAGER/DIGIMANAGER/scheduler/views.py", line 37, in generate_ai_image
    from yourapp.utils import generate_image_sd  # or your AI image generation logic
    ^^^^^^^^^^^^^^^^^^^^^^^^^^^^^^^^^^^^^^^^^^^
ModuleNotFoundError: No module named 'yourapp'
"POST /ai/generate/1/ HTTP/1.1" 500 76713
Internal Server Error: /ai/generate/1/
Traceback (most recent call last):
  File "/home/s1gm9/Documents/Projects/DIGIMANAGER/venv/lib/python3.13/site-packages/django/core/handlers/exception.py", line 55, in inner
    response = get_response(request)
  File "/home/s1gm9/Documents/Projects/DIGIMANAGER/venv/lib/python3.13/site-packages/django/core/handlers/base.py", line 197, in _get_response
    response = wrapped_callback(request, *callback_args, **callback_kwargs)
  File "/home/s1gm9/Documents/Projects/DIGIMANAGER/venv/lib/python3.13/site-packages/django/views/decorators/http.py", line 64, in inner
    return func(request, *args, **kwargs)
  File "/home/s1gm9/Documents/Projects/DIGIMANAGER/venv/lib/python3.13/site-packages/django/views/decorators/csrf.py", line 65, in _view_wrapper
    return view_func(request, *args, **kwargs)
  File "/home/s1gm9/Documents/Projects/DIGIMANAGER/DIGIMANAGER/scheduler/views.py", line 37, in generate_ai_image
    from yourapp.utils import generate_image_sd  # or your AI image generation logic
    ^^^^^^^^^^^^^^^^^^^^^^^^^^^^^^^^^^^^^^^^^^^
ModuleNotFoundError: No module named 'yourapp'
"POST /ai/generate/1/ HTTP/1.1" 500 76657
Internal Server Error: /ai/generate/1/
Traceback (most recent call last):
  File "/home/s1gm9/Documents/Projects/DIGIMANAGER/venv/lib/python3.13/site-packages/django/core/handlers/exception.py", line 55, in inner
    response = get_response(request)
  File "/home/s1gm9/Documents/Projects/DIGIMANAGER/venv/lib/python3.13/site-packages/django/core/handlers/base.py", line 197, in _get_response
    response = wrapped_callback(request, *callback_args, **callback_kwargs)
  File "/home/s1gm9/Documents/Projects/DIGIMANAGER/venv/lib/python3.13/site-packages/django/views/decorators/http.py", line 64, in inner
    return func(request, *args, **kwargs)
  File "/home/s1gm9/Documents/Projects/DIGIMANAGER/venv/lib/python3.13/site-packages/django/views/decorators/csrf.py", line 65, in _view_wrapper
    return view_func(request, *args, **kwargs)
  File "/home/s1gm9/Documents/Projects/DIGIMANAGER/DIGIMANAGER/scheduler/views.py", line 37, in generate_ai_image
    from yourapp.utils import generate_image_sd  # or your AI image generation logic
    ^^^^^^^^^^^^^^^^^^^^^^^^^^^^^^^^^^^^^^^^^^^
ModuleNotFoundError: No module named 'yourapp'
"POST /ai/generate/1/ HTTP/1.1" 500 76657
Internal Server Error: /ai/generate/1/
Traceback (most recent call last):
  File "/home/s1gm9/Documents/Projects/DIGIMANAGER/venv/lib/python3.13/site-packages/django/core/handlers/exception.py", line 55, in inner
    response = get_response(request)
  File "/home/s1gm9/Documents/Projects/DIGIMANAGER/venv/lib/python3.13/site-packages/django/core/handlers/base.py", line 197, in _get_response
    response = wrapped_callback(request, *callback_args, **callback_kwargs)
  File "/home/s1gm9/Documents/Projects/DIGIMANAGER/venv/lib/python3.13/site-packages/django/views/decorators/http.py", line 64, in inner
    return func(request, *args, **kwargs)
  File "/home/s1gm9/Documents/Projects/DIGIMANAGER/venv/lib/python3.13/site-packages/django/views/decorators/csrf.py", line 65, in _view_wrapper
    return view_func(request, *args, **kwargs)
  File "/home/s1gm9/Documents/Projects/DIGIMANAGER/DIGIMANAGER/scheduler/views.py", line 42, in generate_ai_image
    from yourapp.utils import generate_image_sd  # or your AI image generation logic
    ^^^^^^^^^^^^^^^^^^^^^^^^^^^^^^^^^^^^^^^^^^^
ModuleNotFoundError: No module named 'yourapp'
"POST /ai/generate/1/ HTTP/1.1" 500 76665
Internal Server Error: /ai/generate/1/
Traceback (most recent call last):
  File "/home/s1gm9/Documents/Projects/DIGIMANAGER/venv/lib/python3.13/site-packages/django/core/handlers/exception.py", line 55, in inner
    response = get_response(request)
  File "/home/s1gm9/Documents/Projects/DIGIMANAGER/venv/lib/python3.13/site-packages/django/core/handlers/base.py", line 197, in _get_response
    response = wrapped_callback(request, *callback_args, **callback_kwargs)
  File "/home/s1gm9/Documents/Projects/DIGIMANAGER/venv/lib/python3.13/site-packages/django/views/decorators/http.py", line 64, in inner
    return func(request, *args, **kwargs)
  File "/home/s1gm9/Documents/Projects/DIGIMANAGER/venv/lib/python3.13/site-packages/django/views/decorators/csrf.py", line 65, in _view_wrapper
    return view_func(request, *args, **kwargs)
  File "/home/s1gm9/Documents/Projects/DIGIMANAGER/DIGIMANAGER/scheduler/views.py", line 42, in generate_ai_image
    from yourapp.utils import generate_image_sd  # or your AI image generation logic
    ^^^^^^^^^^^^^^^^^^^^^^^^^^^^^^^^^^^^^^^^^^^
ModuleNotFoundError: No module named 'yourapp'
"POST /ai/generate/1/ HTTP/1.1" 500 76665
Internal Server Error: /ai/generate/1/
Traceback (most recent call last):
  File "/home/s1gm9/Documents/Projects/DIGIMANAGER/venv/lib/python3.13/site-packages/django/core/handlers/exception.py", line 55, in inner
    response = get_response(request)
  File "/home/s1gm9/Documents/Projects/DIGIMANAGER/venv/lib/python3.13/site-packages/django/core/handlers/base.py", line 197, in _get_response
    response = wrapped_callback(request, *callback_args, **callback_kwargs)
  File "/home/s1gm9/Documents/Projects/DIGIMANAGER/venv/lib/python3.13/site-packages/django/views/decorators/http.py", line 64, in inner
    return func(request, *args, **kwargs)
  File "/home/s1gm9/Documents/Projects/DIGIMANAGER/venv/lib/python3.13/site-packages/django/views/decorators/csrf.py", line 65, in _view_wrapper
    return view_func(request, *args, **kwargs)
  File "/home/s1gm9/Documents/Projects/DIGIMANAGER/DIGIMANAGER/scheduler/views.py", line 42, in generate_ai_image
    from yourapp.utils import generate_image_sd  # or your AI image generation logic
    ^^^^^^^^^^^^^^^^^^^^^^^^^^^^^^^^^^^^^^^^^^^
ModuleNotFoundError: No module named 'yourapp'
"POST /ai/generate/1/ HTTP/1.1" 500 76655
Internal Server Error: /ai/generate/1/
Traceback (most recent call last):
  File "/home/s1gm9/Documents/Projects/DIGIMANAGER/venv/lib/python3.13/site-packages/django/core/handlers/exception.py", line 55, in inner
    response = get_response(request)
  File "/home/s1gm9/Documents/Projects/DIGIMANAGER/venv/lib/python3.13/site-packages/django/core/handlers/base.py", line 197, in _get_response
    response = wrapped_callback(request, *callback_args, **callback_kwargs)
  File "/home/s1gm9/Documents/Projects/DIGIMANAGER/venv/lib/python3.13/site-packages/django/views/decorators/http.py", line 64, in inner
    return func(request, *args, **kwargs)
  File "/home/s1gm9/Documents/Projects/DIGIMANAGER/venv/lib/python3.13/site-packages/django/views/decorators/csrf.py", line 65, in _view_wrapper
    return view_func(request, *args, **kwargs)
  File "/home/s1gm9/Documents/Projects/DIGIMANAGER/DIGIMANAGER/scheduler/views.py", line 42, in generate_ai_image
    from yourapp.utils import generate_image_sd  # or your AI image generation logic
    ^^^^^^^^^^^^^^^^^^^^^^^^^^^^^^^^^^^^^^^^^^^
ModuleNotFoundError: No module named 'yourapp'
"POST /ai/generate/1/ HTTP/1.1" 500 76656
Internal Server Error: /posts/create/
Traceback (most recent call last):
  File "/home/s1gm9/Documents/Projects/DIGIMANAGER/venv/lib/python3.13/site-packages/django/core/handlers/exception.py", line 55, in inner
    response = get_response(request)
  File "/home/s1gm9/Documents/Projects/DIGIMANAGER/venv/lib/python3.13/site-packages/django/core/handlers/base.py", line 197, in _get_response
    response = wrapped_callback(request, *callback_args, **callback_kwargs)
  File "/home/s1gm9/Documents/Projects/DIGIMANAGER/venv/lib/python3.13/site-packages/django/contrib/auth/decorators.py", line 60, in _view_wrapper
    return view_func(request, *args, **kwargs)
  File "/home/s1gm9/Documents/Projects/DIGIMANAGER/DIGIMANAGER/scheduler/views.py", line 207, in createPost
    return render(request, 'posts/createPost.html', {'form': form, 'post':post})
                                                                          ^^^^
UnboundLocalError: cannot access local variable 'post' where it is not associated with a value
"GET /posts/create/ HTTP/1.1" 500 73705
Internal Server Error: /posts/create/
Traceback (most recent call last):
  File "/home/s1gm9/Documents/Projects/DIGIMANAGER/venv/lib/python3.13/site-packages/django/core/handlers/exception.py", line 55, in inner
    response = get_response(request)
  File "/home/s1gm9/Documents/Projects/DIGIMANAGER/venv/lib/python3.13/site-packages/django/core/handlers/base.py", line 197, in _get_response
    response = wrapped_callback(request, *callback_args, **callback_kwargs)
  File "/home/s1gm9/Documents/Projects/DIGIMANAGER/venv/lib/python3.13/site-packages/django/contrib/auth/decorators.py", line 60, in _view_wrapper
    return view_func(request, *args, **kwargs)
  File "/home/s1gm9/Documents/Projects/DIGIMANAGER/DIGIMANAGER/scheduler/views.py", line 207, in createPost
    return render(request, 'posts/createPost.html', {'form': form, 'post':post})
                                                                          ^^^^
UnboundLocalError: cannot access local variable 'post' where it is not associated with a value
"GET /posts/create/ HTTP/1.1" 500 73536
Internal Server Error: /posts/create/
Traceback (most recent call last):
  File "/home/s1gm9/Documents/Projects/DIGIMANAGER/venv/lib/python3.13/site-packages/django/core/handlers/exception.py", line 55, in inner
    response = get_response(request)
  File "/home/s1gm9/Documents/Projects/DIGIMANAGER/venv/lib/python3.13/site-packages/django/core/handlers/base.py", line 197, in _get_response
    response = wrapped_callback(request, *callback_args, **callback_kwargs)
  File "/home/s1gm9/Documents/Projects/DIGIMANAGER/venv/lib/python3.13/site-packages/django/contrib/auth/decorators.py", line 60, in _view_wrapper
    return view_func(request, *args, **kwargs)
  File "/home/s1gm9/Documents/Projects/DIGIMANAGER/DIGIMANAGER/scheduler/views.py", line 207, in createPost
    return render(request, 'posts/createPost.html', {'form': form, 'post':post})
                                                                          ^^^^
UnboundLocalError: cannot access local variable 'post' where it is not associated with a value
"GET /posts/create/ HTTP/1.1" 500 73536
Internal Server Error: /posts/create/
Traceback (most recent call last):
  File "/home/s1gm9/Documents/Projects/DIGIMANAGER/venv/lib/python3.13/site-packages/django/core/handlers/exception.py", line 55, in inner
    response = get_response(request)
  File "/home/s1gm9/Documents/Projects/DIGIMANAGER/venv/lib/python3.13/site-packages/django/core/handlers/base.py", line 197, in _get_response
    response = wrapped_callback(request, *callback_args, **callback_kwargs)
  File "/home/s1gm9/Documents/Projects/DIGIMANAGER/venv/lib/python3.13/site-packages/django/contrib/auth/decorators.py", line 60, in _view_wrapper
    return view_func(request, *args, **kwargs)
  File "/home/s1gm9/Documents/Projects/DIGIMANAGER/DIGIMANAGER/scheduler/views.py", line 207, in createPost
    return render(request, 'posts/createPost.html', {'form': form, 'post':post})
                                                                          ^^^^
UnboundLocalError: cannot access local variable 'post' where it is not associated with a value
"GET /posts/create/ HTTP/1.1" 500 73536
Internal Server Error: /posts/create/
Traceback (most recent call last):
  File "/home/s1gm9/Documents/Projects/DIGIMANAGER/venv/lib/python3.13/site-packages/django/core/handlers/exception.py", line 55, in inner
    response = get_response(request)
  File "/home/s1gm9/Documents/Projects/DIGIMANAGER/venv/lib/python3.13/site-packages/django/core/handlers/base.py", line 197, in _get_response
    response = wrapped_callback(request, *callback_args, **callback_kwargs)
  File "/home/s1gm9/Documents/Projects/DIGIMANAGER/venv/lib/python3.13/site-packages/django/contrib/auth/decorators.py", line 60, in _view_wrapper
    return view_func(request, *args, **kwargs)
  File "/home/s1gm9/Documents/Projects/DIGIMANAGER/DIGIMANAGER/scheduler/views.py", line 207, in createPost
    return render(request, 'posts/createPost.html', {'form': form, 'post':post})
                                                                          ^^^^
UnboundLocalError: cannot access local variable 'post' where it is not associated with a value
"GET /posts/create/ HTTP/1.1" 500 73536
Internal Server Error: /posts/create/
Traceback (most recent call last):
  File "/home/s1gm9/Documents/Projects/DIGIMANAGER/venv/lib/python3.13/site-packages/django/core/handlers/exception.py", line 55, in inner
    response = get_response(request)
  File "/home/s1gm9/Documents/Projects/DIGIMANAGER/venv/lib/python3.13/site-packages/django/core/handlers/base.py", line 197, in _get_response
    response = wrapped_callback(request, *callback_args, **callback_kwargs)
  File "/home/s1gm9/Documents/Projects/DIGIMANAGER/venv/lib/python3.13/site-packages/django/contrib/auth/decorators.py", line 60, in _view_wrapper
    return view_func(request, *args, **kwargs)
  File "/home/s1gm9/Documents/Projects/DIGIMANAGER/DIGIMANAGER/scheduler/views.py", line 207, in createPost
    return render(request, 'posts/createPost.html', {'form': form, 'post':post})
                                                                          ^^^^
UnboundLocalError: cannot access local variable 'post' where it is not associated with a value
"GET /posts/create/ HTTP/1.1" 500 73536
Internal Server Error: /posts/create/
Traceback (most recent call last):
  File "/home/s1gm9/Documents/Projects/DIGIMANAGER/venv/lib/python3.13/site-packages/django/core/handlers/exception.py", line 55, in inner
    response = get_response(request)
  File "/home/s1gm9/Documents/Projects/DIGIMANAGER/venv/lib/python3.13/site-packages/django/core/handlers/base.py", line 197, in _get_response
    response = wrapped_callback(request, *callback_args, **callback_kwargs)
  File "/home/s1gm9/Documents/Projects/DIGIMANAGER/venv/lib/python3.13/site-packages/django/contrib/auth/decorators.py", line 60, in _view_wrapper
    return view_func(request, *args, **kwargs)
  File "/home/s1gm9/Documents/Projects/DIGIMANAGER/DIGIMANAGER/scheduler/views.py", line 207, in createPost
    return render(request, 'posts/createPost.html', {'form': form, 'post':post})
                                                                          ^^^^
UnboundLocalError: cannot access local variable 'post' where it is not associated with a value
"GET /posts/create/ HTTP/1.1" 500 73536
Internal Server Error: /posts/create/
Traceback (most recent call last):
  File "/home/s1gm9/Documents/Projects/DIGIMANAGER/venv/lib/python3.13/site-packages/django/core/handlers/exception.py", line 55, in inner
    response = get_response(request)
  File "/home/s1gm9/Documents/Projects/DIGIMANAGER/venv/lib/python3.13/site-packages/django/core/handlers/base.py", line 197, in _get_response
    response = wrapped_callback(request, *callback_args, **callback_kwargs)
  File "/home/s1gm9/Documents/Projects/DIGIMANAGER/venv/lib/python3.13/site-packages/django/contrib/auth/decorators.py", line 60, in _view_wrapper
    return view_func(request, *args, **kwargs)
  File "/home/s1gm9/Documents/Projects/DIGIMANAGER/DIGIMANAGER/scheduler/views.py", line 207, in createPost
    return render(request, 'posts/createPost.html',{'form': form})
  File "/home/s1gm9/Documents/Projects/DIGIMANAGER/venv/lib/python3.13/site-packages/django/shortcuts.py", line 25, in render
    content = loader.render_to_string(template_name, context, request, using=using)
  File "/home/s1gm9/Documents/Projects/DIGIMANAGER/venv/lib/python3.13/site-packages/django/template/loader.py", line 62, in render_to_string
    return template.render(context, request)
           ~~~~~~~~~~~~~~~^^^^^^^^^^^^^^^^^^
  File "/home/s1gm9/Documents/Projects/DIGIMANAGER/venv/lib/python3.13/site-packages/django/template/backends/django.py", line 107, in render
    return self.template.render(context)
           ~~~~~~~~~~~~~~~~~~~~^^^^^^^^^
  File "/home/s1gm9/Documents/Projects/DIGIMANAGER/venv/lib/python3.13/site-packages/django/template/base.py", line 171, in render
    return self._render(context)
           ~~~~~~~~~~~~^^^^^^^^^
  File "/home/s1gm9/Documents/Projects/DIGIMANAGER/venv/lib/python3.13/site-packages/django/template/base.py", line 163, in _render
    return self.nodelist.render(context)
           ~~~~~~~~~~~~~~~~~~~~^^^^^^^^^
  File "/home/s1gm9/Documents/Projects/DIGIMANAGER/venv/lib/python3.13/site-packages/django/template/base.py", line 1008, in render
    return SafeString("".join([node.render_annotated(context) for node in self]))
                               ~~~~~~~~~~~~~~~~~~~~~^^^^^^^^^
  File "/home/s1gm9/Documents/Projects/DIGIMANAGER/venv/lib/python3.13/site-packages/django/template/base.py", line 969, in render_annotated
    return self.render(context)
           ~~~~~~~~~~~^^^^^^^^^
  File "/home/s1gm9/Documents/Projects/DIGIMANAGER/venv/lib/python3.13/site-packages/django/template/loader_tags.py", line 159, in render
    return compiled_parent._render(context)
           ~~~~~~~~~~~~~~~~~~~~~~~^^^^^^^^^
  File "/home/s1gm9/Documents/Projects/DIGIMANAGER/venv/lib/python3.13/site-packages/django/template/base.py", line 163, in _render
    return self.nodelist.render(context)
           ~~~~~~~~~~~~~~~~~~~~^^^^^^^^^
  File "/home/s1gm9/Documents/Projects/DIGIMANAGER/venv/lib/python3.13/site-packages/django/template/base.py", line 1008, in render
    return SafeString("".join([node.render_annotated(context) for node in self]))
                               ~~~~~~~~~~~~~~~~~~~~~^^^^^^^^^
  File "/home/s1gm9/Documents/Projects/DIGIMANAGER/venv/lib/python3.13/site-packages/django/template/base.py", line 969, in render_annotated
    return self.render(context)
           ~~~~~~~~~~~^^^^^^^^^
  File "/home/s1gm9/Documents/Projects/DIGIMANAGER/venv/lib/python3.13/site-packages/django/template/loader_tags.py", line 65, in render
    result = block.nodelist.render(context)
  File "/home/s1gm9/Documents/Projects/DIGIMANAGER/venv/lib/python3.13/site-packages/django/template/base.py", line 1008, in render
    return SafeString("".join([node.render_annotated(context) for node in self]))
                               ~~~~~~~~~~~~~~~~~~~~~^^^^^^^^^
  File "/home/s1gm9/Documents/Projects/DIGIMANAGER/venv/lib/python3.13/site-packages/django/template/base.py", line 969, in render_annotated
    return self.render(context)
           ~~~~~~~~~~~^^^^^^^^^
  File "/home/s1gm9/Documents/Projects/DIGIMANAGER/venv/lib/python3.13/site-packages/django/template/defaulttags.py", line 480, in render
    url = reverse(view_name, args=args, kwargs=kwargs, current_app=current_app)
  File "/home/s1gm9/Documents/Projects/DIGIMANAGER/venv/lib/python3.13/site-packages/django/urls/base.py", line 88, in reverse
    return resolver._reverse_with_prefix(view, prefix, *args, **kwargs)
           ~~~~~~~~~~~~~~~~~~~~~~~~~~~~~^^^^^^^^^^^^^^^^^^^^^^^^^^^^^^^
  File "/home/s1gm9/Documents/Projects/DIGIMANAGER/venv/lib/python3.13/site-packages/django/urls/resolvers.py", line 831, in _reverse_with_prefix
    raise NoReverseMatch(msg)
django.urls.exceptions.NoReverseMatch: Reverse for 'generate_ai_image' with no arguments not found. 1 pattern(s) tried: ['ai/generate/(?P<post_id>[0-9]+)/\\Z']
"GET /posts/create/ HTTP/1.1" 500 160848
Internal Server Error: /ai/generate/
Traceback (most recent call last):
  File "/home/s1gm9/Documents/Projects/DIGIMANAGER/venv/lib/python3.13/site-packages/django/core/handlers/exception.py", line 55, in inner
    response = get_response(request)
  File "/home/s1gm9/Documents/Projects/DIGIMANAGER/venv/lib/python3.13/site-packages/django/core/handlers/base.py", line 197, in _get_response
    response = wrapped_callback(request, *callback_args, **callback_kwargs)
  File "/home/s1gm9/Documents/Projects/DIGIMANAGER/venv/lib/python3.13/site-packages/django/views/decorators/http.py", line 64, in inner
    return func(request, *args, **kwargs)
  File "/home/s1gm9/Documents/Projects/DIGIMANAGER/venv/lib/python3.13/site-packages/django/views/decorators/csrf.py", line 65, in _view_wrapper
    return view_func(request, *args, **kwargs)
TypeError: generate_ai_image() missing 1 required positional argument: 'post_id'
"POST /ai/generate/ HTTP/1.1" 500 73100
Internal Server Error: /ai/generate/
"POST /ai/generate/ HTTP/1.1" 500 37
Internal Server Error: /ai/generate/
"POST /ai/generate/ HTTP/1.1" 500 37
Internal Server Error: /ai/generate/
"POST /ai/generate/ HTTP/1.1" 500 37
Internal Server Error: /ai/generate/
"POST /ai/generate/ HTTP/1.1" 500 37
Internal Server Error: /creator-dashboard/
Traceback (most recent call last):
  File "/home/s1gm9/Documents/Projects/DIGIMANAGER/venv/lib/python3.13/site-packages/django/core/handlers/exception.py", line 55, in inner
    response = get_response(request)
  File "/home/s1gm9/Documents/Projects/DIGIMANAGER/venv/lib/python3.13/site-packages/django/core/handlers/base.py", line 197, in _get_response
    response = wrapped_callback(request, *callback_args, **callback_kwargs)
  File "/home/s1gm9/Documents/Projects/DIGIMANAGER/venv/lib/python3.13/site-packages/django/contrib/auth/decorators.py", line 60, in _view_wrapper
    return view_func(request, *args, **kwargs)
  File "/home/s1gm9/Documents/Projects/DIGIMANAGER/DIGIMANAGER/scheduler/views.py", line 422, in creatorDashboard
    return render(request, 'dashboards/creatorDashboard.html', {
        'posts': my_posts,
        'platforms': platforms,
    })
  File "/home/s1gm9/Documents/Projects/DIGIMANAGER/venv/lib/python3.13/site-packages/django/shortcuts.py", line 25, in render
    content = loader.render_to_string(template_name, context, request, using=using)
  File "/home/s1gm9/Documents/Projects/DIGIMANAGER/venv/lib/python3.13/site-packages/django/template/loader.py", line 62, in render_to_string
    return template.render(context, request)
           ~~~~~~~~~~~~~~~^^^^^^^^^^^^^^^^^^
  File "/home/s1gm9/Documents/Projects/DIGIMANAGER/venv/lib/python3.13/site-packages/django/template/backends/django.py", line 107, in render
    return self.template.render(context)
           ~~~~~~~~~~~~~~~~~~~~^^^^^^^^^
  File "/home/s1gm9/Documents/Projects/DIGIMANAGER/venv/lib/python3.13/site-packages/django/template/base.py", line 171, in render
    return self._render(context)
           ~~~~~~~~~~~~^^^^^^^^^
  File "/home/s1gm9/Documents/Projects/DIGIMANAGER/venv/lib/python3.13/site-packages/django/template/base.py", line 163, in _render
    return self.nodelist.render(context)
           ~~~~~~~~~~~~~~~~~~~~^^^^^^^^^
  File "/home/s1gm9/Documents/Projects/DIGIMANAGER/venv/lib/python3.13/site-packages/django/template/base.py", line 1008, in render
    return SafeString("".join([node.render_annotated(context) for node in self]))
                               ~~~~~~~~~~~~~~~~~~~~~^^^^^^^^^
  File "/home/s1gm9/Documents/Projects/DIGIMANAGER/venv/lib/python3.13/site-packages/django/template/base.py", line 969, in render_annotated
    return self.render(context)
           ~~~~~~~~~~~^^^^^^^^^
  File "/home/s1gm9/Documents/Projects/DIGIMANAGER/venv/lib/python3.13/site-packages/django/template/loader_tags.py", line 159, in render
    return compiled_parent._render(context)
           ~~~~~~~~~~~~~~~~~~~~~~~^^^^^^^^^
  File "/home/s1gm9/Documents/Projects/DIGIMANAGER/venv/lib/python3.13/site-packages/django/template/base.py", line 163, in _render
    return self.nodelist.render(context)
           ~~~~~~~~~~~~~~~~~~~~^^^^^^^^^
  File "/home/s1gm9/Documents/Projects/DIGIMANAGER/venv/lib/python3.13/site-packages/django/template/base.py", line 1008, in render
    return SafeString("".join([node.render_annotated(context) for node in self]))
                               ~~~~~~~~~~~~~~~~~~~~~^^^^^^^^^
  File "/home/s1gm9/Documents/Projects/DIGIMANAGER/venv/lib/python3.13/site-packages/django/template/base.py", line 969, in render_annotated
    return self.render(context)
           ~~~~~~~~~~~^^^^^^^^^
  File "/home/s1gm9/Documents/Projects/DIGIMANAGER/venv/lib/python3.13/site-packages/django/template/loader_tags.py", line 65, in render
    result = block.nodelist.render(context)
  File "/home/s1gm9/Documents/Projects/DIGIMANAGER/venv/lib/python3.13/site-packages/django/template/base.py", line 1008, in render
    return SafeString("".join([node.render_annotated(context) for node in self]))
                               ~~~~~~~~~~~~~~~~~~~~~^^^^^^^^^
  File "/home/s1gm9/Documents/Projects/DIGIMANAGER/venv/lib/python3.13/site-packages/django/template/base.py", line 969, in render_annotated
    return self.render(context)
           ~~~~~~~~~~~^^^^^^^^^
  File "/home/s1gm9/Documents/Projects/DIGIMANAGER/venv/lib/python3.13/site-packages/django/template/defaulttags.py", line 327, in render
    return nodelist.render(context)
           ~~~~~~~~~~~~~~~^^^^^^^^^
  File "/home/s1gm9/Documents/Projects/DIGIMANAGER/venv/lib/python3.13/site-packages/django/template/base.py", line 1008, in render
    return SafeString("".join([node.render_annotated(context) for node in self]))
                               ~~~~~~~~~~~~~~~~~~~~~^^^^^^^^^
  File "/home/s1gm9/Documents/Projects/DIGIMANAGER/venv/lib/python3.13/site-packages/django/template/base.py", line 969, in render_annotated
    return self.render(context)
           ~~~~~~~~~~~^^^^^^^^^
  File "/home/s1gm9/Documents/Projects/DIGIMANAGER/venv/lib/python3.13/site-packages/django/template/defaulttags.py", line 243, in render
    nodelist.append(node.render_annotated(context))
                    ~~~~~~~~~~~~~~~~~~~~~^^^^^^^^^
  File "/home/s1gm9/Documents/Projects/DIGIMANAGER/venv/lib/python3.13/site-packages/django/template/base.py", line 969, in render_annotated
    return self.render(context)
           ~~~~~~~~~~~^^^^^^^^^
  File "/home/s1gm9/Documents/Projects/DIGIMANAGER/venv/lib/python3.13/site-packages/django/template/defaulttags.py", line 480, in render
    url = reverse(view_name, args=args, kwargs=kwargs, current_app=current_app)
  File "/home/s1gm9/Documents/Projects/DIGIMANAGER/venv/lib/python3.13/site-packages/django/urls/base.py", line 88, in reverse
    return resolver._reverse_with_prefix(view, prefix, *args, **kwargs)
           ~~~~~~~~~~~~~~~~~~~~~~~~~~~~~^^^^^^^^^^^^^^^^^^^^^^^^^^^^^^^
  File "/home/s1gm9/Documents/Projects/DIGIMANAGER/venv/lib/python3.13/site-packages/django/urls/resolvers.py", line 831, in _reverse_with_prefix
    raise NoReverseMatch(msg)
django.urls.exceptions.NoReverseMatch: Reverse for 'viewPost' with arguments '(1,)' not found. 1 pattern(s) tried: ['posts/view/\\Z']
"GET /creator-dashboard/ HTTP/1.1" 500 191072
Internal Server Error: /creator-dashboard/
Traceback (most recent call last):
  File "/home/s1gm9/Documents/Projects/DIGIMANAGER/venv/lib/python3.13/site-packages/django/core/handlers/exception.py", line 55, in inner
    response = get_response(request)
  File "/home/s1gm9/Documents/Projects/DIGIMANAGER/venv/lib/python3.13/site-packages/django/core/handlers/base.py", line 197, in _get_response
    response = wrapped_callback(request, *callback_args, **callback_kwargs)
  File "/home/s1gm9/Documents/Projects/DIGIMANAGER/venv/lib/python3.13/site-packages/django/contrib/auth/decorators.py", line 60, in _view_wrapper
    return view_func(request, *args, **kwargs)
  File "/home/s1gm9/Documents/Projects/DIGIMANAGER/DIGIMANAGER/scheduler/views.py", line 422, in creatorDashboard
    return render(request, 'dashboards/creatorDashboard.html', {
        'posts': my_posts,
        'platforms': platforms,
    })
  File "/home/s1gm9/Documents/Projects/DIGIMANAGER/venv/lib/python3.13/site-packages/django/shortcuts.py", line 25, in render
    content = loader.render_to_string(template_name, context, request, using=using)
  File "/home/s1gm9/Documents/Projects/DIGIMANAGER/venv/lib/python3.13/site-packages/django/template/loader.py", line 62, in render_to_string
    return template.render(context, request)
           ~~~~~~~~~~~~~~~^^^^^^^^^^^^^^^^^^
  File "/home/s1gm9/Documents/Projects/DIGIMANAGER/venv/lib/python3.13/site-packages/django/template/backends/django.py", line 107, in render
    return self.template.render(context)
           ~~~~~~~~~~~~~~~~~~~~^^^^^^^^^
  File "/home/s1gm9/Documents/Projects/DIGIMANAGER/venv/lib/python3.13/site-packages/django/template/base.py", line 171, in render
    return self._render(context)
           ~~~~~~~~~~~~^^^^^^^^^
  File "/home/s1gm9/Documents/Projects/DIGIMANAGER/venv/lib/python3.13/site-packages/django/template/base.py", line 163, in _render
    return self.nodelist.render(context)
           ~~~~~~~~~~~~~~~~~~~~^^^^^^^^^
  File "/home/s1gm9/Documents/Projects/DIGIMANAGER/venv/lib/python3.13/site-packages/django/template/base.py", line 1008, in render
    return SafeString("".join([node.render_annotated(context) for node in self]))
                               ~~~~~~~~~~~~~~~~~~~~~^^^^^^^^^
  File "/home/s1gm9/Documents/Projects/DIGIMANAGER/venv/lib/python3.13/site-packages/django/template/base.py", line 969, in render_annotated
    return self.render(context)
           ~~~~~~~~~~~^^^^^^^^^
  File "/home/s1gm9/Documents/Projects/DIGIMANAGER/venv/lib/python3.13/site-packages/django/template/loader_tags.py", line 159, in render
    return compiled_parent._render(context)
           ~~~~~~~~~~~~~~~~~~~~~~~^^^^^^^^^
  File "/home/s1gm9/Documents/Projects/DIGIMANAGER/venv/lib/python3.13/site-packages/django/template/base.py", line 163, in _render
    return self.nodelist.render(context)
           ~~~~~~~~~~~~~~~~~~~~^^^^^^^^^
  File "/home/s1gm9/Documents/Projects/DIGIMANAGER/venv/lib/python3.13/site-packages/django/template/base.py", line 1008, in render
    return SafeString("".join([node.render_annotated(context) for node in self]))
                               ~~~~~~~~~~~~~~~~~~~~~^^^^^^^^^
  File "/home/s1gm9/Documents/Projects/DIGIMANAGER/venv/lib/python3.13/site-packages/django/template/base.py", line 969, in render_annotated
    return self.render(context)
           ~~~~~~~~~~~^^^^^^^^^
  File "/home/s1gm9/Documents/Projects/DIGIMANAGER/venv/lib/python3.13/site-packages/django/template/loader_tags.py", line 65, in render
    result = block.nodelist.render(context)
  File "/home/s1gm9/Documents/Projects/DIGIMANAGER/venv/lib/python3.13/site-packages/django/template/base.py", line 1008, in render
    return SafeString("".join([node.render_annotated(context) for node in self]))
                               ~~~~~~~~~~~~~~~~~~~~~^^^^^^^^^
  File "/home/s1gm9/Documents/Projects/DIGIMANAGER/venv/lib/python3.13/site-packages/django/template/base.py", line 969, in render_annotated
    return self.render(context)
           ~~~~~~~~~~~^^^^^^^^^
  File "/home/s1gm9/Documents/Projects/DIGIMANAGER/venv/lib/python3.13/site-packages/django/template/defaulttags.py", line 327, in render
    return nodelist.render(context)
           ~~~~~~~~~~~~~~~^^^^^^^^^
  File "/home/s1gm9/Documents/Projects/DIGIMANAGER/venv/lib/python3.13/site-packages/django/template/base.py", line 1008, in render
    return SafeString("".join([node.render_annotated(context) for node in self]))
                               ~~~~~~~~~~~~~~~~~~~~~^^^^^^^^^
  File "/home/s1gm9/Documents/Projects/DIGIMANAGER/venv/lib/python3.13/site-packages/django/template/base.py", line 969, in render_annotated
    return self.render(context)
           ~~~~~~~~~~~^^^^^^^^^
  File "/home/s1gm9/Documents/Projects/DIGIMANAGER/venv/lib/python3.13/site-packages/django/template/defaulttags.py", line 243, in render
    nodelist.append(node.render_annotated(context))
                    ~~~~~~~~~~~~~~~~~~~~~^^^^^^^^^
  File "/home/s1gm9/Documents/Projects/DIGIMANAGER/venv/lib/python3.13/site-packages/django/template/base.py", line 969, in render_annotated
    return self.render(context)
           ~~~~~~~~~~~^^^^^^^^^
  File "/home/s1gm9/Documents/Projects/DIGIMANAGER/venv/lib/python3.13/site-packages/django/template/defaulttags.py", line 480, in render
    url = reverse(view_name, args=args, kwargs=kwargs, current_app=current_app)
  File "/home/s1gm9/Documents/Projects/DIGIMANAGER/venv/lib/python3.13/site-packages/django/urls/base.py", line 88, in reverse
    return resolver._reverse_with_prefix(view, prefix, *args, **kwargs)
           ~~~~~~~~~~~~~~~~~~~~~~~~~~~~~^^^^^^^^^^^^^^^^^^^^^^^^^^^^^^^
  File "/home/s1gm9/Documents/Projects/DIGIMANAGER/venv/lib/python3.13/site-packages/django/urls/resolvers.py", line 831, in _reverse_with_prefix
    raise NoReverseMatch(msg)
django.urls.exceptions.NoReverseMatch: Reverse for 'viewPost' with arguments '(1,)' not found. 1 pattern(s) tried: ['posts/view/\\Z']
"GET /creator-dashboard/ HTTP/1.1" 500 192017
Internal Server Error: /creator-dashboard/
Traceback (most recent call last):
  File "/home/s1gm9/Documents/Projects/DIGIMANAGER/venv/lib/python3.13/site-packages/django/core/handlers/exception.py", line 55, in inner
    response = get_response(request)
  File "/home/s1gm9/Documents/Projects/DIGIMANAGER/venv/lib/python3.13/site-packages/django/core/handlers/base.py", line 197, in _get_response
    response = wrapped_callback(request, *callback_args, **callback_kwargs)
  File "/home/s1gm9/Documents/Projects/DIGIMANAGER/venv/lib/python3.13/site-packages/django/contrib/auth/decorators.py", line 60, in _view_wrapper
    return view_func(request, *args, **kwargs)
  File "/home/s1gm9/Documents/Projects/DIGIMANAGER/DIGIMANAGER/scheduler/views.py", line 422, in creatorDashboard
    return render(request, 'dashboards/creatorDashboard.html', {
        'posts': my_posts,
        'platforms': platforms,
    })
  File "/home/s1gm9/Documents/Projects/DIGIMANAGER/venv/lib/python3.13/site-packages/django/shortcuts.py", line 25, in render
    content = loader.render_to_string(template_name, context, request, using=using)
  File "/home/s1gm9/Documents/Projects/DIGIMANAGER/venv/lib/python3.13/site-packages/django/template/loader.py", line 62, in render_to_string
    return template.render(context, request)
           ~~~~~~~~~~~~~~~^^^^^^^^^^^^^^^^^^
  File "/home/s1gm9/Documents/Projects/DIGIMANAGER/venv/lib/python3.13/site-packages/django/template/backends/django.py", line 107, in render
    return self.template.render(context)
           ~~~~~~~~~~~~~~~~~~~~^^^^^^^^^
  File "/home/s1gm9/Documents/Projects/DIGIMANAGER/venv/lib/python3.13/site-packages/django/template/base.py", line 171, in render
    return self._render(context)
           ~~~~~~~~~~~~^^^^^^^^^
  File "/home/s1gm9/Documents/Projects/DIGIMANAGER/venv/lib/python3.13/site-packages/django/template/base.py", line 163, in _render
    return self.nodelist.render(context)
           ~~~~~~~~~~~~~~~~~~~~^^^^^^^^^
  File "/home/s1gm9/Documents/Projects/DIGIMANAGER/venv/lib/python3.13/site-packages/django/template/base.py", line 1008, in render
    return SafeString("".join([node.render_annotated(context) for node in self]))
                               ~~~~~~~~~~~~~~~~~~~~~^^^^^^^^^
  File "/home/s1gm9/Documents/Projects/DIGIMANAGER/venv/lib/python3.13/site-packages/django/template/base.py", line 969, in render_annotated
    return self.render(context)
           ~~~~~~~~~~~^^^^^^^^^
  File "/home/s1gm9/Documents/Projects/DIGIMANAGER/venv/lib/python3.13/site-packages/django/template/loader_tags.py", line 159, in render
    return compiled_parent._render(context)
           ~~~~~~~~~~~~~~~~~~~~~~~^^^^^^^^^
  File "/home/s1gm9/Documents/Projects/DIGIMANAGER/venv/lib/python3.13/site-packages/django/template/base.py", line 163, in _render
    return self.nodelist.render(context)
           ~~~~~~~~~~~~~~~~~~~~^^^^^^^^^
  File "/home/s1gm9/Documents/Projects/DIGIMANAGER/venv/lib/python3.13/site-packages/django/template/base.py", line 1008, in render
    return SafeString("".join([node.render_annotated(context) for node in self]))
                               ~~~~~~~~~~~~~~~~~~~~~^^^^^^^^^
  File "/home/s1gm9/Documents/Projects/DIGIMANAGER/venv/lib/python3.13/site-packages/django/template/base.py", line 969, in render_annotated
    return self.render(context)
           ~~~~~~~~~~~^^^^^^^^^
  File "/home/s1gm9/Documents/Projects/DIGIMANAGER/venv/lib/python3.13/site-packages/django/template/loader_tags.py", line 65, in render
    result = block.nodelist.render(context)
  File "/home/s1gm9/Documents/Projects/DIGIMANAGER/venv/lib/python3.13/site-packages/django/template/base.py", line 1008, in render
    return SafeString("".join([node.render_annotated(context) for node in self]))
                               ~~~~~~~~~~~~~~~~~~~~~^^^^^^^^^
  File "/home/s1gm9/Documents/Projects/DIGIMANAGER/venv/lib/python3.13/site-packages/django/template/base.py", line 969, in render_annotated
    return self.render(context)
           ~~~~~~~~~~~^^^^^^^^^
  File "/home/s1gm9/Documents/Projects/DIGIMANAGER/venv/lib/python3.13/site-packages/django/template/defaulttags.py", line 327, in render
    return nodelist.render(context)
           ~~~~~~~~~~~~~~~^^^^^^^^^
  File "/home/s1gm9/Documents/Projects/DIGIMANAGER/venv/lib/python3.13/site-packages/django/template/base.py", line 1008, in render
    return SafeString("".join([node.render_annotated(context) for node in self]))
                               ~~~~~~~~~~~~~~~~~~~~~^^^^^^^^^
  File "/home/s1gm9/Documents/Projects/DIGIMANAGER/venv/lib/python3.13/site-packages/django/template/base.py", line 969, in render_annotated
    return self.render(context)
           ~~~~~~~~~~~^^^^^^^^^
  File "/home/s1gm9/Documents/Projects/DIGIMANAGER/venv/lib/python3.13/site-packages/django/template/defaulttags.py", line 243, in render
    nodelist.append(node.render_annotated(context))
                    ~~~~~~~~~~~~~~~~~~~~~^^^^^^^^^
  File "/home/s1gm9/Documents/Projects/DIGIMANAGER/venv/lib/python3.13/site-packages/django/template/base.py", line 969, in render_annotated
    return self.render(context)
           ~~~~~~~~~~~^^^^^^^^^
  File "/home/s1gm9/Documents/Projects/DIGIMANAGER/venv/lib/python3.13/site-packages/django/template/defaulttags.py", line 480, in render
    url = reverse(view_name, args=args, kwargs=kwargs, current_app=current_app)
  File "/home/s1gm9/Documents/Projects/DIGIMANAGER/venv/lib/python3.13/site-packages/django/urls/base.py", line 88, in reverse
    return resolver._reverse_with_prefix(view, prefix, *args, **kwargs)
           ~~~~~~~~~~~~~~~~~~~~~~~~~~~~~^^^^^^^^^^^^^^^^^^^^^^^^^^^^^^^
  File "/home/s1gm9/Documents/Projects/DIGIMANAGER/venv/lib/python3.13/site-packages/django/urls/resolvers.py", line 831, in _reverse_with_prefix
    raise NoReverseMatch(msg)
django.urls.exceptions.NoReverseMatch: Reverse for 'viewPost' with arguments '(1,)' not found. 1 pattern(s) tried: ['posts/view/\\Z']
"GET /creator-dashboard/ HTTP/1.1" 500 191600
Internal Server Error: /creator-dashboard/
Traceback (most recent call last):
  File "/home/s1gm9/Documents/Projects/DIGIMANAGER/venv/lib/python3.13/site-packages/django/core/handlers/exception.py", line 55, in inner
    response = get_response(request)
  File "/home/s1gm9/Documents/Projects/DIGIMANAGER/venv/lib/python3.13/site-packages/django/core/handlers/base.py", line 197, in _get_response
    response = wrapped_callback(request, *callback_args, **callback_kwargs)
  File "/home/s1gm9/Documents/Projects/DIGIMANAGER/venv/lib/python3.13/site-packages/django/contrib/auth/decorators.py", line 60, in _view_wrapper
    return view_func(request, *args, **kwargs)
  File "/home/s1gm9/Documents/Projects/DIGIMANAGER/DIGIMANAGER/scheduler/views.py", line 422, in creatorDashboard
    return render(request, 'dashboards/creatorDashboard.html', {
        'posts': my_posts,
        'platforms': platforms,
    })
  File "/home/s1gm9/Documents/Projects/DIGIMANAGER/venv/lib/python3.13/site-packages/django/shortcuts.py", line 25, in render
    content = loader.render_to_string(template_name, context, request, using=using)
  File "/home/s1gm9/Documents/Projects/DIGIMANAGER/venv/lib/python3.13/site-packages/django/template/loader.py", line 62, in render_to_string
    return template.render(context, request)
           ~~~~~~~~~~~~~~~^^^^^^^^^^^^^^^^^^
  File "/home/s1gm9/Documents/Projects/DIGIMANAGER/venv/lib/python3.13/site-packages/django/template/backends/django.py", line 107, in render
    return self.template.render(context)
           ~~~~~~~~~~~~~~~~~~~~^^^^^^^^^
  File "/home/s1gm9/Documents/Projects/DIGIMANAGER/venv/lib/python3.13/site-packages/django/template/base.py", line 171, in render
    return self._render(context)
           ~~~~~~~~~~~~^^^^^^^^^
  File "/home/s1gm9/Documents/Projects/DIGIMANAGER/venv/lib/python3.13/site-packages/django/template/base.py", line 163, in _render
    return self.nodelist.render(context)
           ~~~~~~~~~~~~~~~~~~~~^^^^^^^^^
  File "/home/s1gm9/Documents/Projects/DIGIMANAGER/venv/lib/python3.13/site-packages/django/template/base.py", line 1008, in render
    return SafeString("".join([node.render_annotated(context) for node in self]))
                               ~~~~~~~~~~~~~~~~~~~~~^^^^^^^^^
  File "/home/s1gm9/Documents/Projects/DIGIMANAGER/venv/lib/python3.13/site-packages/django/template/base.py", line 969, in render_annotated
    return self.render(context)
           ~~~~~~~~~~~^^^^^^^^^
  File "/home/s1gm9/Documents/Projects/DIGIMANAGER/venv/lib/python3.13/site-packages/django/template/loader_tags.py", line 159, in render
    return compiled_parent._render(context)
           ~~~~~~~~~~~~~~~~~~~~~~~^^^^^^^^^
  File "/home/s1gm9/Documents/Projects/DIGIMANAGER/venv/lib/python3.13/site-packages/django/template/base.py", line 163, in _render
    return self.nodelist.render(context)
           ~~~~~~~~~~~~~~~~~~~~^^^^^^^^^
  File "/home/s1gm9/Documents/Projects/DIGIMANAGER/venv/lib/python3.13/site-packages/django/template/base.py", line 1008, in render
    return SafeString("".join([node.render_annotated(context) for node in self]))
                               ~~~~~~~~~~~~~~~~~~~~~^^^^^^^^^
  File "/home/s1gm9/Documents/Projects/DIGIMANAGER/venv/lib/python3.13/site-packages/django/template/base.py", line 969, in render_annotated
    return self.render(context)
           ~~~~~~~~~~~^^^^^^^^^
  File "/home/s1gm9/Documents/Projects/DIGIMANAGER/venv/lib/python3.13/site-packages/django/template/loader_tags.py", line 65, in render
    result = block.nodelist.render(context)
  File "/home/s1gm9/Documents/Projects/DIGIMANAGER/venv/lib/python3.13/site-packages/django/template/base.py", line 1008, in render
    return SafeString("".join([node.render_annotated(context) for node in self]))
                               ~~~~~~~~~~~~~~~~~~~~~^^^^^^^^^
  File "/home/s1gm9/Documents/Projects/DIGIMANAGER/venv/lib/python3.13/site-packages/django/template/base.py", line 969, in render_annotated
    return self.render(context)
           ~~~~~~~~~~~^^^^^^^^^
  File "/home/s1gm9/Documents/Projects/DIGIMANAGER/venv/lib/python3.13/site-packages/django/template/defaulttags.py", line 327, in render
    return nodelist.render(context)
           ~~~~~~~~~~~~~~~^^^^^^^^^
  File "/home/s1gm9/Documents/Projects/DIGIMANAGER/venv/lib/python3.13/site-packages/django/template/base.py", line 1008, in render
    return SafeString("".join([node.render_annotated(context) for node in self]))
                               ~~~~~~~~~~~~~~~~~~~~~^^^^^^^^^
  File "/home/s1gm9/Documents/Projects/DIGIMANAGER/venv/lib/python3.13/site-packages/django/template/base.py", line 969, in render_annotated
    return self.render(context)
           ~~~~~~~~~~~^^^^^^^^^
  File "/home/s1gm9/Documents/Projects/DIGIMANAGER/venv/lib/python3.13/site-packages/django/template/defaulttags.py", line 243, in render
    nodelist.append(node.render_annotated(context))
                    ~~~~~~~~~~~~~~~~~~~~~^^^^^^^^^
  File "/home/s1gm9/Documents/Projects/DIGIMANAGER/venv/lib/python3.13/site-packages/django/template/base.py", line 969, in render_annotated
    return self.render(context)
           ~~~~~~~~~~~^^^^^^^^^
  File "/home/s1gm9/Documents/Projects/DIGIMANAGER/venv/lib/python3.13/site-packages/django/template/defaulttags.py", line 480, in render
    url = reverse(view_name, args=args, kwargs=kwargs, current_app=current_app)
  File "/home/s1gm9/Documents/Projects/DIGIMANAGER/venv/lib/python3.13/site-packages/django/urls/base.py", line 88, in reverse
    return resolver._reverse_with_prefix(view, prefix, *args, **kwargs)
           ~~~~~~~~~~~~~~~~~~~~~~~~~~~~~^^^^^^^^^^^^^^^^^^^^^^^^^^^^^^^
  File "/home/s1gm9/Documents/Projects/DIGIMANAGER/venv/lib/python3.13/site-packages/django/urls/resolvers.py", line 831, in _reverse_with_prefix
    raise NoReverseMatch(msg)
django.urls.exceptions.NoReverseMatch: Reverse for 'viewPost' with arguments '(1,)' not found. 1 pattern(s) tried: ['posts/view/\\Z']
"GET /creator-dashboard/ HTTP/1.1" 500 191600
Internal Server Error: /creator-dashboard/
Traceback (most recent call last):
  File "/home/s1gm9/Documents/Projects/DIGIMANAGER/venv/lib/python3.13/site-packages/django/core/handlers/exception.py", line 55, in inner
    response = get_response(request)
  File "/home/s1gm9/Documents/Projects/DIGIMANAGER/venv/lib/python3.13/site-packages/django/core/handlers/base.py", line 197, in _get_response
    response = wrapped_callback(request, *callback_args, **callback_kwargs)
  File "/home/s1gm9/Documents/Projects/DIGIMANAGER/venv/lib/python3.13/site-packages/django/contrib/auth/decorators.py", line 60, in _view_wrapper
    return view_func(request, *args, **kwargs)
  File "/home/s1gm9/Documents/Projects/DIGIMANAGER/DIGIMANAGER/scheduler/views.py", line 422, in creatorDashboard
    return render(request, 'dashboards/creatorDashboard.html', {
        'posts': my_posts,
        'platforms': platforms,
    })
  File "/home/s1gm9/Documents/Projects/DIGIMANAGER/venv/lib/python3.13/site-packages/django/shortcuts.py", line 25, in render
    content = loader.render_to_string(template_name, context, request, using=using)
  File "/home/s1gm9/Documents/Projects/DIGIMANAGER/venv/lib/python3.13/site-packages/django/template/loader.py", line 62, in render_to_string
    return template.render(context, request)
           ~~~~~~~~~~~~~~~^^^^^^^^^^^^^^^^^^
  File "/home/s1gm9/Documents/Projects/DIGIMANAGER/venv/lib/python3.13/site-packages/django/template/backends/django.py", line 107, in render
    return self.template.render(context)
           ~~~~~~~~~~~~~~~~~~~~^^^^^^^^^
  File "/home/s1gm9/Documents/Projects/DIGIMANAGER/venv/lib/python3.13/site-packages/django/template/base.py", line 171, in render
    return self._render(context)
           ~~~~~~~~~~~~^^^^^^^^^
  File "/home/s1gm9/Documents/Projects/DIGIMANAGER/venv/lib/python3.13/site-packages/django/template/base.py", line 163, in _render
    return self.nodelist.render(context)
           ~~~~~~~~~~~~~~~~~~~~^^^^^^^^^
  File "/home/s1gm9/Documents/Projects/DIGIMANAGER/venv/lib/python3.13/site-packages/django/template/base.py", line 1008, in render
    return SafeString("".join([node.render_annotated(context) for node in self]))
                               ~~~~~~~~~~~~~~~~~~~~~^^^^^^^^^
  File "/home/s1gm9/Documents/Projects/DIGIMANAGER/venv/lib/python3.13/site-packages/django/template/base.py", line 969, in render_annotated
    return self.render(context)
           ~~~~~~~~~~~^^^^^^^^^
  File "/home/s1gm9/Documents/Projects/DIGIMANAGER/venv/lib/python3.13/site-packages/django/template/loader_tags.py", line 159, in render
    return compiled_parent._render(context)
           ~~~~~~~~~~~~~~~~~~~~~~~^^^^^^^^^
  File "/home/s1gm9/Documents/Projects/DIGIMANAGER/venv/lib/python3.13/site-packages/django/template/base.py", line 163, in _render
    return self.nodelist.render(context)
           ~~~~~~~~~~~~~~~~~~~~^^^^^^^^^
  File "/home/s1gm9/Documents/Projects/DIGIMANAGER/venv/lib/python3.13/site-packages/django/template/base.py", line 1008, in render
    return SafeString("".join([node.render_annotated(context) for node in self]))
                               ~~~~~~~~~~~~~~~~~~~~~^^^^^^^^^
  File "/home/s1gm9/Documents/Projects/DIGIMANAGER/venv/lib/python3.13/site-packages/django/template/base.py", line 969, in render_annotated
    return self.render(context)
           ~~~~~~~~~~~^^^^^^^^^
  File "/home/s1gm9/Documents/Projects/DIGIMANAGER/venv/lib/python3.13/site-packages/django/template/loader_tags.py", line 65, in render
    result = block.nodelist.render(context)
  File "/home/s1gm9/Documents/Projects/DIGIMANAGER/venv/lib/python3.13/site-packages/django/template/base.py", line 1008, in render
    return SafeString("".join([node.render_annotated(context) for node in self]))
                               ~~~~~~~~~~~~~~~~~~~~~^^^^^^^^^
  File "/home/s1gm9/Documents/Projects/DIGIMANAGER/venv/lib/python3.13/site-packages/django/template/base.py", line 969, in render_annotated
    return self.render(context)
           ~~~~~~~~~~~^^^^^^^^^
  File "/home/s1gm9/Documents/Projects/DIGIMANAGER/venv/lib/python3.13/site-packages/django/template/defaulttags.py", line 327, in render
    return nodelist.render(context)
           ~~~~~~~~~~~~~~~^^^^^^^^^
  File "/home/s1gm9/Documents/Projects/DIGIMANAGER/venv/lib/python3.13/site-packages/django/template/base.py", line 1008, in render
    return SafeString("".join([node.render_annotated(context) for node in self]))
                               ~~~~~~~~~~~~~~~~~~~~~^^^^^^^^^
  File "/home/s1gm9/Documents/Projects/DIGIMANAGER/venv/lib/python3.13/site-packages/django/template/base.py", line 969, in render_annotated
    return self.render(context)
           ~~~~~~~~~~~^^^^^^^^^
  File "/home/s1gm9/Documents/Projects/DIGIMANAGER/venv/lib/python3.13/site-packages/django/template/defaulttags.py", line 243, in render
    nodelist.append(node.render_annotated(context))
                    ~~~~~~~~~~~~~~~~~~~~~^^^^^^^^^
  File "/home/s1gm9/Documents/Projects/DIGIMANAGER/venv/lib/python3.13/site-packages/django/template/base.py", line 969, in render_annotated
    return self.render(context)
           ~~~~~~~~~~~^^^^^^^^^
  File "/home/s1gm9/Documents/Projects/DIGIMANAGER/venv/lib/python3.13/site-packages/django/template/defaulttags.py", line 480, in render
    url = reverse(view_name, args=args, kwargs=kwargs, current_app=current_app)
  File "/home/s1gm9/Documents/Projects/DIGIMANAGER/venv/lib/python3.13/site-packages/django/urls/base.py", line 88, in reverse
    return resolver._reverse_with_prefix(view, prefix, *args, **kwargs)
           ~~~~~~~~~~~~~~~~~~~~~~~~~~~~~^^^^^^^^^^^^^^^^^^^^^^^^^^^^^^^
  File "/home/s1gm9/Documents/Projects/DIGIMANAGER/venv/lib/python3.13/site-packages/django/urls/resolvers.py", line 831, in _reverse_with_prefix
    raise NoReverseMatch(msg)
django.urls.exceptions.NoReverseMatch: Reverse for 'deletePost' with arguments '(1,)' not found. 1 pattern(s) tried: ['posts/delete/\\Z']
"GET /creator-dashboard/ HTTP/1.1" 500 191794
Internal Server Error: /post/1/edit/
Traceback (most recent call last):
  File "/home/s1gm9/Documents/Projects/DIGIMANAGER/venv/lib/python3.13/site-packages/django/core/handlers/exception.py", line 55, in inner
    response = get_response(request)
  File "/home/s1gm9/Documents/Projects/DIGIMANAGER/venv/lib/python3.13/site-packages/django/core/handlers/base.py", line 197, in _get_response
    response = wrapped_callback(request, *callback_args, **callback_kwargs)
  File "/home/s1gm9/Documents/Projects/DIGIMANAGER/DIGIMANAGER/scheduler/views.py", line 297, in editPost
    return render(request, 'contentgen/createPost.html', {
        'form': form,
        'post': post,  # pass this for AI previews and JS updates
    })
  File "/home/s1gm9/Documents/Projects/DIGIMANAGER/venv/lib/python3.13/site-packages/django/shortcuts.py", line 25, in render
    content = loader.render_to_string(template_name, context, request, using=using)
  File "/home/s1gm9/Documents/Projects/DIGIMANAGER/venv/lib/python3.13/site-packages/django/template/loader.py", line 61, in render_to_string
    template = get_template(template_name, using=using)
  File "/home/s1gm9/Documents/Projects/DIGIMANAGER/venv/lib/python3.13/site-packages/django/template/loader.py", line 19, in get_template
    raise TemplateDoesNotExist(template_name, chain=chain)
django.template.exceptions.TemplateDoesNotExist: contentgen/createPost.html
"GET /post/1/edit/ HTTP/1.1" 500 84720
Internal Server Error: /post/1/edit/
Traceback (most recent call last):
  File "/home/s1gm9/Documents/Projects/DIGIMANAGER/venv/lib/python3.13/site-packages/django/core/handlers/exception.py", line 55, in inner
    response = get_response(request)
  File "/home/s1gm9/Documents/Projects/DIGIMANAGER/venv/lib/python3.13/site-packages/django/core/handlers/base.py", line 197, in _get_response
    response = wrapped_callback(request, *callback_args, **callback_kwargs)
  File "/home/s1gm9/Documents/Projects/DIGIMANAGER/venv/lib/python3.13/site-packages/django/contrib/auth/decorators.py", line 60, in _view_wrapper
    return view_func(request, *args, **kwargs)
TypeError: editPost() got an unexpected keyword argument 'pk'
"GET /post/1/edit/ HTTP/1.1" 500 69188
Internal Server Error: /post/1/edit/
Traceback (most recent call last):
  File "/home/s1gm9/Documents/Projects/DIGIMANAGER/venv/lib/python3.13/site-packages/django/core/handlers/exception.py", line 55, in inner
    response = get_response(request)
  File "/home/s1gm9/Documents/Projects/DIGIMANAGER/venv/lib/python3.13/site-packages/django/core/handlers/base.py", line 197, in _get_response
    response = wrapped_callback(request, *callback_args, **callback_kwargs)
  File "/home/s1gm9/Documents/Projects/DIGIMANAGER/venv/lib/python3.13/site-packages/django/contrib/auth/decorators.py", line 60, in _view_wrapper
    return view_func(request, *args, **kwargs)
TypeError: editPost() got an unexpected keyword argument 'pk'
"GET /post/1/edit/ HTTP/1.1" 500 69188
Internal Server Error: /post/1/edit/
Traceback (most recent call last):
  File "/home/s1gm9/Documents/Projects/DIGIMANAGER/venv/lib/python3.13/site-packages/django/core/handlers/exception.py", line 55, in inner
    response = get_response(request)
  File "/home/s1gm9/Documents/Projects/DIGIMANAGER/venv/lib/python3.13/site-packages/django/core/handlers/base.py", line 197, in _get_response
    response = wrapped_callback(request, *callback_args, **callback_kwargs)
  File "/home/s1gm9/Documents/Projects/DIGIMANAGER/venv/lib/python3.13/site-packages/django/contrib/auth/decorators.py", line 60, in _view_wrapper
    return view_func(request, *args, **kwargs)
TypeError: editPost() got an unexpected keyword argument 'pk'
"GET /post/1/edit/ HTTP/1.1" 500 69345
Internal Server Error: /post/1/edit/
Traceback (most recent call last):
  File "/home/s1gm9/Documents/Projects/DIGIMANAGER/venv/lib/python3.13/site-packages/django/core/handlers/exception.py", line 55, in inner
    response = get_response(request)
  File "/home/s1gm9/Documents/Projects/DIGIMANAGER/venv/lib/python3.13/site-packages/django/core/handlers/base.py", line 197, in _get_response
    response = wrapped_callback(request, *callback_args, **callback_kwargs)
  File "/home/s1gm9/Documents/Projects/DIGIMANAGER/venv/lib/python3.13/site-packages/django/contrib/auth/decorators.py", line 60, in _view_wrapper
    return view_func(request, *args, **kwargs)
TypeError: editPost() got an unexpected keyword argument 'pk'
"GET /post/1/edit/ HTTP/1.1" 500 69188
Internal Server Error: /post/1/edit/
Traceback (most recent call last):
  File "/home/s1gm9/Documents/Projects/DIGIMANAGER/venv/lib/python3.13/site-packages/django/core/handlers/exception.py", line 55, in inner
    response = get_response(request)
  File "/home/s1gm9/Documents/Projects/DIGIMANAGER/venv/lib/python3.13/site-packages/django/core/handlers/base.py", line 197, in _get_response
    response = wrapped_callback(request, *callback_args, **callback_kwargs)
  File "/home/s1gm9/Documents/Projects/DIGIMANAGER/venv/lib/python3.13/site-packages/django/contrib/auth/decorators.py", line 60, in _view_wrapper
    return view_func(request, *args, **kwargs)
TypeError: editPost() got an unexpected keyword argument 'pk'
"GET /post/1/edit/ HTTP/1.1" 500 69188
Internal Server Error: /post/1/edit/
Traceback (most recent call last):
  File "/home/s1gm9/Documents/Projects/DIGIMANAGER/venv/lib/python3.13/site-packages/django/core/handlers/exception.py", line 55, in inner
    response = get_response(request)
  File "/home/s1gm9/Documents/Projects/DIGIMANAGER/venv/lib/python3.13/site-packages/django/core/handlers/base.py", line 197, in _get_response
    response = wrapped_callback(request, *callback_args, **callback_kwargs)
  File "/home/s1gm9/Documents/Projects/DIGIMANAGER/venv/lib/python3.13/site-packages/django/contrib/auth/decorators.py", line 60, in _view_wrapper
    return view_func(request, *args, **kwargs)
TypeError: editPost() got an unexpected keyword argument 'pk'
"GET /post/1/edit/ HTTP/1.1" 500 69188
Internal Server Error: /post/1/edit/
Traceback (most recent call last):
  File "/home/s1gm9/Documents/Projects/DIGIMANAGER/venv/lib/python3.13/site-packages/django/core/handlers/exception.py", line 55, in inner
    response = get_response(request)
  File "/home/s1gm9/Documents/Projects/DIGIMANAGER/venv/lib/python3.13/site-packages/django/core/handlers/base.py", line 197, in _get_response
    response = wrapped_callback(request, *callback_args, **callback_kwargs)
  File "/home/s1gm9/Documents/Projects/DIGIMANAGER/venv/lib/python3.13/site-packages/django/contrib/auth/decorators.py", line 60, in _view_wrapper
    return view_func(request, *args, **kwargs)
TypeError: editPost() got an unexpected keyword argument 'pk'
"GET /post/1/edit/ HTTP/1.1" 500 69345
Internal Server Error: /post/1/edit/
Traceback (most recent call last):
  File "/home/s1gm9/Documents/Projects/DIGIMANAGER/venv/lib/python3.13/site-packages/django/core/handlers/exception.py", line 55, in inner
    response = get_response(request)
  File "/home/s1gm9/Documents/Projects/DIGIMANAGER/venv/lib/python3.13/site-packages/django/core/handlers/base.py", line 197, in _get_response
    response = wrapped_callback(request, *callback_args, **callback_kwargs)
  File "/home/s1gm9/Documents/Projects/DIGIMANAGER/venv/lib/python3.13/site-packages/django/contrib/auth/decorators.py", line 60, in _view_wrapper
    return view_func(request, *args, **kwargs)
TypeError: editPost() got an unexpected keyword argument 'pk'
"GET /post/1/edit/ HTTP/1.1" 500 69188
Internal Server Error: /post/1/edit/
Traceback (most recent call last):
  File "/home/s1gm9/Documents/Projects/DIGIMANAGER/venv/lib/python3.13/site-packages/django/core/handlers/exception.py", line 55, in inner
    response = get_response(request)
  File "/home/s1gm9/Documents/Projects/DIGIMANAGER/venv/lib/python3.13/site-packages/django/core/handlers/base.py", line 197, in _get_response
    response = wrapped_callback(request, *callback_args, **callback_kwargs)
  File "/home/s1gm9/Documents/Projects/DIGIMANAGER/venv/lib/python3.13/site-packages/django/contrib/auth/decorators.py", line 60, in _view_wrapper
    return view_func(request, *args, **kwargs)
TypeError: editPost() got an unexpected keyword argument 'pk'
"GET /post/1/edit/ HTTP/1.1" 500 69188
Internal Server Error: /post/1/edit/
Traceback (most recent call last):
  File "/home/s1gm9/Documents/Projects/DIGIMANAGER/venv/lib/python3.13/site-packages/django/core/handlers/exception.py", line 55, in inner
    response = get_response(request)
  File "/home/s1gm9/Documents/Projects/DIGIMANAGER/venv/lib/python3.13/site-packages/django/core/handlers/base.py", line 197, in _get_response
    response = wrapped_callback(request, *callback_args, **callback_kwargs)
  File "/home/s1gm9/Documents/Projects/DIGIMANAGER/venv/lib/python3.13/site-packages/django/contrib/auth/decorators.py", line 60, in _view_wrapper
    return view_func(request, *args, **kwargs)
TypeError: editPost() got an unexpected keyword argument 'pk'
"GET /post/1/edit/ HTTP/1.1" 500 69345
Internal Server Error: /post/1/edit/
Traceback (most recent call last):
  File "/home/s1gm9/Documents/Projects/DIGIMANAGER/venv/lib/python3.13/site-packages/django/core/handlers/exception.py", line 55, in inner
    response = get_response(request)
  File "/home/s1gm9/Documents/Projects/DIGIMANAGER/venv/lib/python3.13/site-packages/django/core/handlers/base.py", line 197, in _get_response
    response = wrapped_callback(request, *callback_args, **callback_kwargs)
  File "/home/s1gm9/Documents/Projects/DIGIMANAGER/venv/lib/python3.13/site-packages/django/contrib/auth/decorators.py", line 60, in _view_wrapper
    return view_func(request, *args, **kwargs)
TypeError: editPost() got an unexpected keyword argument 'pk'
"GET /post/1/edit/ HTTP/1.1" 500 69357
Internal Server Error: /post/1/edit/
Traceback (most recent call last):
  File "/home/s1gm9/Documents/Projects/DIGIMANAGER/venv/lib/python3.13/site-packages/django/core/handlers/exception.py", line 55, in inner
    response = get_response(request)
  File "/home/s1gm9/Documents/Projects/DIGIMANAGER/venv/lib/python3.13/site-packages/django/core/handlers/base.py", line 197, in _get_response
    response = wrapped_callback(request, *callback_args, **callback_kwargs)
  File "/home/s1gm9/Documents/Projects/DIGIMANAGER/venv/lib/python3.13/site-packages/django/contrib/auth/decorators.py", line 60, in _view_wrapper
    return view_func(request, *args, **kwargs)
TypeError: editPost() got an unexpected keyword argument 'pk'
"GET /post/1/edit/ HTTP/1.1" 500 69188
Internal Server Error: /post/1/edit/
Traceback (most recent call last):
  File "/home/s1gm9/Documents/Projects/DIGIMANAGER/venv/lib/python3.13/site-packages/django/core/handlers/exception.py", line 55, in inner
    response = get_response(request)
  File "/home/s1gm9/Documents/Projects/DIGIMANAGER/venv/lib/python3.13/site-packages/django/core/handlers/base.py", line 197, in _get_response
    response = wrapped_callback(request, *callback_args, **callback_kwargs)
  File "/home/s1gm9/Documents/Projects/DIGIMANAGER/venv/lib/python3.13/site-packages/django/contrib/auth/decorators.py", line 60, in _view_wrapper
    return view_func(request, *args, **kwargs)
  File "/home/s1gm9/Documents/Projects/DIGIMANAGER/DIGIMANAGER/scheduler/views.py", line 270, in editPost
    post = get_object_or_404(Post, post_id)
  File "/home/s1gm9/Documents/Projects/DIGIMANAGER/venv/lib/python3.13/site-packages/django/shortcuts.py", line 86, in get_object_or_404
    return queryset.get(*args, **kwargs)
           ~~~~~~~~~~~~^^^^^^^^^^^^^^^^^
  File "/home/s1gm9/Documents/Projects/DIGIMANAGER/venv/lib/python3.13/site-packages/django/db/models/query.py", line 635, in get
    clone = self._chain() if self.query.combinator else self.filter(*args, **kwargs)
                                                        ~~~~~~~~~~~^^^^^^^^^^^^^^^^^
  File "/home/s1gm9/Documents/Projects/DIGIMANAGER/venv/lib/python3.13/site-packages/django/db/models/query.py", line 1476, in filter
    return self._filter_or_exclude(False, args, kwargs)
           ~~~~~~~~~~~~~~~~~~~~~~~^^^^^^^^^^^^^^^^^^^^^
  File "/home/s1gm9/Documents/Projects/DIGIMANAGER/venv/lib/python3.13/site-packages/django/db/models/query.py", line 1494, in _filter_or_exclude
    clone._filter_or_exclude_inplace(negate, args, kwargs)
    ~~~~~~~~~~~~~~~~~~~~~~~~~~~~~~~~^^^^^^^^^^^^^^^^^^^^^^
  File "/home/s1gm9/Documents/Projects/DIGIMANAGER/venv/lib/python3.13/site-packages/django/db/models/query.py", line 1501, in _filter_or_exclude_inplace
    self._query.add_q(Q(*args, **kwargs))
    ~~~~~~~~~~~~~~~~~^^^^^^^^^^^^^^^^^^^^
  File "/home/s1gm9/Documents/Projects/DIGIMANAGER/venv/lib/python3.13/site-packages/django/db/models/sql/query.py", line 1609, in add_q
    clause, _ = self._add_q(q_object, self.used_aliases)
                ~~~~~~~~~~~^^^^^^^^^^^^^^^^^^^^^^^^^^^^^
  File "/home/s1gm9/Documents/Projects/DIGIMANAGER/venv/lib/python3.13/site-packages/django/db/models/sql/query.py", line 1641, in _add_q
    child_clause, needed_inner = self.build_filter(
                                 ~~~~~~~~~~~~~~~~~^
        child,
        ^^^^^^
    ...<7 lines>...
        update_join_types=update_join_types,
        ^^^^^^^^^^^^^^^^^^^^^^^^^^^^^^^^^^^^
    )
    ^
  File "/home/s1gm9/Documents/Projects/DIGIMANAGER/venv/lib/python3.13/site-packages/django/db/models/sql/query.py", line 1488, in build_filter
    arg, value = filter_expr
    ^^^^^^^^^^
TypeError: cannot unpack non-iterable int object
"GET /post/1/edit/ HTTP/1.1" 500 111658
Internal Server Error: /post/1/edit/
Traceback (most recent call last):
  File "/home/s1gm9/Documents/Projects/DIGIMANAGER/venv/lib/python3.13/site-packages/django/core/handlers/exception.py", line 55, in inner
    response = get_response(request)
  File "/home/s1gm9/Documents/Projects/DIGIMANAGER/venv/lib/python3.13/site-packages/django/core/handlers/base.py", line 197, in _get_response
    response = wrapped_callback(request, *callback_args, **callback_kwargs)
  File "/home/s1gm9/Documents/Projects/DIGIMANAGER/venv/lib/python3.13/site-packages/django/contrib/auth/decorators.py", line 60, in _view_wrapper
    return view_func(request, *args, **kwargs)
  File "/home/s1gm9/Documents/Projects/DIGIMANAGER/DIGIMANAGER/scheduler/views.py", line 272, in editPost
    if request.user != post.author:
                       ^^^^^^^^^^^
AttributeError: 'Post' object has no attribute 'author'
"GET /post/1/edit/ HTTP/1.1" 500 73302
Internal Server Error: /post/1/edit/
Traceback (most recent call last):
  File "/home/s1gm9/Documents/Projects/DIGIMANAGER/venv/lib/python3.13/site-packages/django/core/handlers/exception.py", line 55, in inner
    response = get_response(request)
  File "/home/s1gm9/Documents/Projects/DIGIMANAGER/venv/lib/python3.13/site-packages/django/core/handlers/base.py", line 197, in _get_response
    response = wrapped_callback(request, *callback_args, **callback_kwargs)
  File "/home/s1gm9/Documents/Projects/DIGIMANAGER/venv/lib/python3.13/site-packages/django/contrib/auth/decorators.py", line 60, in _view_wrapper
    return view_func(request, *args, **kwargs)
  File "/home/s1gm9/Documents/Projects/DIGIMANAGER/DIGIMANAGER/scheduler/views.py", line 294, in editPost
    return render(request, 'createPost.html', context)
  File "/home/s1gm9/Documents/Projects/DIGIMANAGER/venv/lib/python3.13/site-packages/django/shortcuts.py", line 25, in render
    content = loader.render_to_string(template_name, context, request, using=using)
  File "/home/s1gm9/Documents/Projects/DIGIMANAGER/venv/lib/python3.13/site-packages/django/template/loader.py", line 61, in render_to_string
    template = get_template(template_name, using=using)
  File "/home/s1gm9/Documents/Projects/DIGIMANAGER/venv/lib/python3.13/site-packages/django/template/loader.py", line 19, in get_template
    raise TemplateDoesNotExist(template_name, chain=chain)
django.template.exceptions.TemplateDoesNotExist: createPost.html
"GET /post/1/edit/ HTTP/1.1" 500 89872
Internal Server Error: /post/1/edit/
Traceback (most recent call last):
  File "/home/s1gm9/Documents/Projects/DIGIMANAGER/venv/lib/python3.13/site-packages/django/core/handlers/exception.py", line 55, in inner
    response = get_response(request)
  File "/home/s1gm9/Documents/Projects/DIGIMANAGER/venv/lib/python3.13/site-packages/django/core/handlers/base.py", line 197, in _get_response
    response = wrapped_callback(request, *callback_args, **callback_kwargs)
  File "/home/s1gm9/Documents/Projects/DIGIMANAGER/venv/lib/python3.13/site-packages/django/contrib/auth/decorators.py", line 60, in _view_wrapper
    return view_func(request, *args, **kwargs)
  File "/home/s1gm9/Documents/Projects/DIGIMANAGER/DIGIMANAGER/scheduler/views.py", line 272, in editPost
    if request.user_id != post.user_id:
       ^^^^^^^^^^^^^^^
AttributeError: 'WSGIRequest' object has no attribute 'user_id'
"GET /post/1/edit/ HTTP/1.1" 500 73318
Internal Server Error: /post/1/edit/
Traceback (most recent call last):
  File "/home/s1gm9/Documents/Projects/DIGIMANAGER/venv/lib/python3.13/site-packages/django/core/handlers/exception.py", line 55, in inner
    response = get_response(request)
  File "/home/s1gm9/Documents/Projects/DIGIMANAGER/venv/lib/python3.13/site-packages/django/core/handlers/base.py", line 197, in _get_response
    response = wrapped_callback(request, *callback_args, **callback_kwargs)
  File "/home/s1gm9/Documents/Projects/DIGIMANAGER/venv/lib/python3.13/site-packages/django/contrib/auth/decorators.py", line 60, in _view_wrapper
    return view_func(request, *args, **kwargs)
  File "/home/s1gm9/Documents/Projects/DIGIMANAGER/DIGIMANAGER/scheduler/views.py", line 272, in editPost
    if request.user_id != post.user_id:
       ^^^^^^^^^^^^^^^
AttributeError: 'WSGIRequest' object has no attribute 'user_id'
"GET /post/1/edit/ HTTP/1.1" 500 73318
Internal Server Error: /post/1/edit/
Traceback (most recent call last):
  File "/home/s1gm9/Documents/Projects/DIGIMANAGER/venv/lib/python3.13/site-packages/django/core/handlers/exception.py", line 55, in inner
    response = get_response(request)
  File "/home/s1gm9/Documents/Projects/DIGIMANAGER/venv/lib/python3.13/site-packages/django/core/handlers/base.py", line 197, in _get_response
    response = wrapped_callback(request, *callback_args, **callback_kwargs)
  File "/home/s1gm9/Documents/Projects/DIGIMANAGER/venv/lib/python3.13/site-packages/django/contrib/auth/decorators.py", line 60, in _view_wrapper
    return view_func(request, *args, **kwargs)
  File "/home/s1gm9/Documents/Projects/DIGIMANAGER/DIGIMANAGER/scheduler/views.py", line 294, in editPost
    return render(request, 'createPost.html', context)
  File "/home/s1gm9/Documents/Projects/DIGIMANAGER/venv/lib/python3.13/site-packages/django/shortcuts.py", line 25, in render
    content = loader.render_to_string(template_name, context, request, using=using)
  File "/home/s1gm9/Documents/Projects/DIGIMANAGER/venv/lib/python3.13/site-packages/django/template/loader.py", line 61, in render_to_string
    template = get_template(template_name, using=using)
  File "/home/s1gm9/Documents/Projects/DIGIMANAGER/venv/lib/python3.13/site-packages/django/template/loader.py", line 19, in get_template
    raise TemplateDoesNotExist(template_name, chain=chain)
django.template.exceptions.TemplateDoesNotExist: createPost.html
"GET /post/1/edit/ HTTP/1.1" 500 89872
Internal Server Error: /post/1/edit/
Traceback (most recent call last):
  File "/home/s1gm9/Documents/Projects/DIGIMANAGER/venv/lib/python3.13/site-packages/django/core/handlers/exception.py", line 55, in inner
    response = get_response(request)
  File "/home/s1gm9/Documents/Projects/DIGIMANAGER/venv/lib/python3.13/site-packages/django/core/handlers/base.py", line 197, in _get_response
    response = wrapped_callback(request, *callback_args, **callback_kwargs)
  File "/home/s1gm9/Documents/Projects/DIGIMANAGER/venv/lib/python3.13/site-packages/django/contrib/auth/decorators.py", line 60, in _view_wrapper
    return view_func(request, *args, **kwargs)
  File "/home/s1gm9/Documents/Projects/DIGIMANAGER/DIGIMANAGER/scheduler/views.py", line 294, in editPost
    return render(request, 'createPost.html', context)
  File "/home/s1gm9/Documents/Projects/DIGIMANAGER/venv/lib/python3.13/site-packages/django/shortcuts.py", line 25, in render
    content = loader.render_to_string(template_name, context, request, using=using)
  File "/home/s1gm9/Documents/Projects/DIGIMANAGER/venv/lib/python3.13/site-packages/django/template/loader.py", line 61, in render_to_string
    template = get_template(template_name, using=using)
  File "/home/s1gm9/Documents/Projects/DIGIMANAGER/venv/lib/python3.13/site-packages/django/template/loader.py", line 19, in get_template
    raise TemplateDoesNotExist(template_name, chain=chain)
django.template.exceptions.TemplateDoesNotExist: createPost.html
"GET /post/1/edit/ HTTP/1.1" 500 89872
Internal Server Error: /post/1/edit/
Traceback (most recent call last):
  File "/home/s1gm9/Documents/Projects/DIGIMANAGER/venv/lib/python3.13/site-packages/django/core/handlers/exception.py", line 55, in inner
    response = get_response(request)
  File "/home/s1gm9/Documents/Projects/DIGIMANAGER/venv/lib/python3.13/site-packages/django/core/handlers/base.py", line 197, in _get_response
    response = wrapped_callback(request, *callback_args, **callback_kwargs)
  File "/home/s1gm9/Documents/Projects/DIGIMANAGER/venv/lib/python3.13/site-packages/django/contrib/auth/decorators.py", line 60, in _view_wrapper
    return view_func(request, *args, **kwargs)
  File "/home/s1gm9/Documents/Projects/DIGIMANAGER/DIGIMANAGER/scheduler/views.py", line 294, in editPost
    return render(request, 'createPost.html', context)
  File "/home/s1gm9/Documents/Projects/DIGIMANAGER/venv/lib/python3.13/site-packages/django/shortcuts.py", line 25, in render
    content = loader.render_to_string(template_name, context, request, using=using)
  File "/home/s1gm9/Documents/Projects/DIGIMANAGER/venv/lib/python3.13/site-packages/django/template/loader.py", line 61, in render_to_string
    template = get_template(template_name, using=using)
  File "/home/s1gm9/Documents/Projects/DIGIMANAGER/venv/lib/python3.13/site-packages/django/template/loader.py", line 19, in get_template
    raise TemplateDoesNotExist(template_name, chain=chain)
django.template.exceptions.TemplateDoesNotExist: createPost.html
"GET /post/1/edit/ HTTP/1.1" 500 89872
Internal Server Error: /post/1/edit/
Traceback (most recent call last):
  File "/home/s1gm9/Documents/Projects/DIGIMANAGER/venv/lib/python3.13/site-packages/django/core/handlers/exception.py", line 55, in inner
    response = get_response(request)
  File "/home/s1gm9/Documents/Projects/DIGIMANAGER/venv/lib/python3.13/site-packages/django/core/handlers/base.py", line 197, in _get_response
    response = wrapped_callback(request, *callback_args, **callback_kwargs)
  File "/home/s1gm9/Documents/Projects/DIGIMANAGER/venv/lib/python3.13/site-packages/django/contrib/auth/decorators.py", line 60, in _view_wrapper
    return view_func(request, *args, **kwargs)
  File "/home/s1gm9/Documents/Projects/DIGIMANAGER/DIGIMANAGER/scheduler/views.py", line 294, in editPost
    return render(request, 'createPost.html', context)
  File "/home/s1gm9/Documents/Projects/DIGIMANAGER/venv/lib/python3.13/site-packages/django/shortcuts.py", line 25, in render
    content = loader.render_to_string(template_name, context, request, using=using)
  File "/home/s1gm9/Documents/Projects/DIGIMANAGER/venv/lib/python3.13/site-packages/django/template/loader.py", line 61, in render_to_string
    template = get_template(template_name, using=using)
  File "/home/s1gm9/Documents/Projects/DIGIMANAGER/venv/lib/python3.13/site-packages/django/template/loader.py", line 19, in get_template
    raise TemplateDoesNotExist(template_name, chain=chain)
django.template.exceptions.TemplateDoesNotExist: createPost.html
"GET /post/1/edit/ HTTP/1.1" 500 89872
Internal Server Error: /post/1/edit/
Traceback (most recent call last):
  File "/home/s1gm9/Documents/Projects/DIGIMANAGER/venv/lib/python3.13/site-packages/django/core/handlers/exception.py", line 55, in inner
    response = get_response(request)
  File "/home/s1gm9/Documents/Projects/DIGIMANAGER/venv/lib/python3.13/site-packages/django/core/handlers/base.py", line 197, in _get_response
    response = wrapped_callback(request, *callback_args, **callback_kwargs)
  File "/home/s1gm9/Documents/Projects/DIGIMANAGER/venv/lib/python3.13/site-packages/django/contrib/auth/decorators.py", line 60, in _view_wrapper
    return view_func(request, *args, **kwargs)
  File "/home/s1gm9/Documents/Projects/DIGIMANAGER/DIGIMANAGER/scheduler/views.py", line 294, in editPost
    return render(request, 'createPost.html', context)
  File "/home/s1gm9/Documents/Projects/DIGIMANAGER/venv/lib/python3.13/site-packages/django/shortcuts.py", line 25, in render
    content = loader.render_to_string(template_name, context, request, using=using)
  File "/home/s1gm9/Documents/Projects/DIGIMANAGER/venv/lib/python3.13/site-packages/django/template/loader.py", line 61, in render_to_string
    template = get_template(template_name, using=using)
  File "/home/s1gm9/Documents/Projects/DIGIMANAGER/venv/lib/python3.13/site-packages/django/template/loader.py", line 19, in get_template
    raise TemplateDoesNotExist(template_name, chain=chain)
django.template.exceptions.TemplateDoesNotExist: createPost.html
"GET /post/1/edit/ HTTP/1.1" 500 89872
Internal Server Error: /post/1/edit/
Traceback (most recent call last):
  File "/home/s1gm9/Documents/Projects/DIGIMANAGER/venv/lib/python3.13/site-packages/django/core/handlers/exception.py", line 55, in inner
    response = get_response(request)
  File "/home/s1gm9/Documents/Projects/DIGIMANAGER/venv/lib/python3.13/site-packages/django/core/handlers/base.py", line 197, in _get_response
    response = wrapped_callback(request, *callback_args, **callback_kwargs)
  File "/home/s1gm9/Documents/Projects/DIGIMANAGER/venv/lib/python3.13/site-packages/django/contrib/auth/decorators.py", line 60, in _view_wrapper
    return view_func(request, *args, **kwargs)
  File "/home/s1gm9/Documents/Projects/DIGIMANAGER/DIGIMANAGER/scheduler/views.py", line 294, in editPost
    return render(request, 'createPost.html', context)
  File "/home/s1gm9/Documents/Projects/DIGIMANAGER/venv/lib/python3.13/site-packages/django/shortcuts.py", line 25, in render
    content = loader.render_to_string(template_name, context, request, using=using)
  File "/home/s1gm9/Documents/Projects/DIGIMANAGER/venv/lib/python3.13/site-packages/django/template/loader.py", line 61, in render_to_string
    template = get_template(template_name, using=using)
  File "/home/s1gm9/Documents/Projects/DIGIMANAGER/venv/lib/python3.13/site-packages/django/template/loader.py", line 19, in get_template
    raise TemplateDoesNotExist(template_name, chain=chain)
django.template.exceptions.TemplateDoesNotExist: createPost.html
"GET /post/1/edit/ HTTP/1.1" 500 89872
Internal Server Error: /post/1/edit/
Traceback (most recent call last):
  File "/home/s1gm9/Documents/Projects/DIGIMANAGER/venv/lib/python3.13/site-packages/django/core/handlers/exception.py", line 55, in inner
    response = get_response(request)
  File "/home/s1gm9/Documents/Projects/DIGIMANAGER/venv/lib/python3.13/site-packages/django/core/handlers/base.py", line 197, in _get_response
    response = wrapped_callback(request, *callback_args, **callback_kwargs)
  File "/home/s1gm9/Documents/Projects/DIGIMANAGER/venv/lib/python3.13/site-packages/django/contrib/auth/decorators.py", line 60, in _view_wrapper
    return view_func(request, *args, **kwargs)
  File "/home/s1gm9/Documents/Projects/DIGIMANAGER/DIGIMANAGER/scheduler/views.py", line 294, in editPost
    return render(request, 'createPost.html', context)
  File "/home/s1gm9/Documents/Projects/DIGIMANAGER/venv/lib/python3.13/site-packages/django/shortcuts.py", line 25, in render
    content = loader.render_to_string(template_name, context, request, using=using)
  File "/home/s1gm9/Documents/Projects/DIGIMANAGER/venv/lib/python3.13/site-packages/django/template/loader.py", line 61, in render_to_string
    template = get_template(template_name, using=using)
  File "/home/s1gm9/Documents/Projects/DIGIMANAGER/venv/lib/python3.13/site-packages/django/template/loader.py", line 19, in get_template
    raise TemplateDoesNotExist(template_name, chain=chain)
django.template.exceptions.TemplateDoesNotExist: createPost.html
"GET /post/1/edit/ HTTP/1.1" 500 89872
Internal Server Error: /platforms/manage/
Traceback (most recent call last):
  File "/home/s1gm9/Documents/Projects/DIGIMANAGER/venv/lib/python3.13/site-packages/django/core/handlers/exception.py", line 55, in inner
    response = get_response(request)
  File "/home/s1gm9/Documents/Projects/DIGIMANAGER/venv/lib/python3.13/site-packages/django/core/handlers/base.py", line 197, in _get_response
    response = wrapped_callback(request, *callback_args, **callback_kwargs)
  File "/home/s1gm9/Documents/Projects/DIGIMANAGER/venv/lib/python3.13/site-packages/django/contrib/auth/decorators.py", line 60, in _view_wrapper
    return view_func(request, *args, **kwargs)
  File "/home/s1gm9/Documents/Projects/DIGIMANAGER/DIGIMANAGER/scheduler/views.py", line 362, in managePlatforms
    return render(request, 'platforms/managePlatforms.html', {
        'form': form,
        'platforms': platforms,
    })
  File "/home/s1gm9/Documents/Projects/DIGIMANAGER/venv/lib/python3.13/site-packages/django/shortcuts.py", line 25, in render
    content = loader.render_to_string(template_name, context, request, using=using)
  File "/home/s1gm9/Documents/Projects/DIGIMANAGER/venv/lib/python3.13/site-packages/django/template/loader.py", line 62, in render_to_string
    return template.render(context, request)
           ~~~~~~~~~~~~~~~^^^^^^^^^^^^^^^^^^
  File "/home/s1gm9/Documents/Projects/DIGIMANAGER/venv/lib/python3.13/site-packages/django/template/backends/django.py", line 107, in render
    return self.template.render(context)
           ~~~~~~~~~~~~~~~~~~~~^^^^^^^^^
  File "/home/s1gm9/Documents/Projects/DIGIMANAGER/venv/lib/python3.13/site-packages/django/template/base.py", line 171, in render
    return self._render(context)
           ~~~~~~~~~~~~^^^^^^^^^
  File "/home/s1gm9/Documents/Projects/DIGIMANAGER/venv/lib/python3.13/site-packages/django/template/base.py", line 163, in _render
    return self.nodelist.render(context)
           ~~~~~~~~~~~~~~~~~~~~^^^^^^^^^
  File "/home/s1gm9/Documents/Projects/DIGIMANAGER/venv/lib/python3.13/site-packages/django/template/base.py", line 1008, in render
    return SafeString("".join([node.render_annotated(context) for node in self]))
                               ~~~~~~~~~~~~~~~~~~~~~^^^^^^^^^
  File "/home/s1gm9/Documents/Projects/DIGIMANAGER/venv/lib/python3.13/site-packages/django/template/base.py", line 969, in render_annotated
    return self.render(context)
           ~~~~~~~~~~~^^^^^^^^^
  File "/home/s1gm9/Documents/Projects/DIGIMANAGER/venv/lib/python3.13/site-packages/django/template/loader_tags.py", line 159, in render
    return compiled_parent._render(context)
           ~~~~~~~~~~~~~~~~~~~~~~~^^^^^^^^^
  File "/home/s1gm9/Documents/Projects/DIGIMANAGER/venv/lib/python3.13/site-packages/django/template/base.py", line 163, in _render
    return self.nodelist.render(context)
           ~~~~~~~~~~~~~~~~~~~~^^^^^^^^^
  File "/home/s1gm9/Documents/Projects/DIGIMANAGER/venv/lib/python3.13/site-packages/django/template/base.py", line 1008, in render
    return SafeString("".join([node.render_annotated(context) for node in self]))
                               ~~~~~~~~~~~~~~~~~~~~~^^^^^^^^^
  File "/home/s1gm9/Documents/Projects/DIGIMANAGER/venv/lib/python3.13/site-packages/django/template/base.py", line 969, in render_annotated
    return self.render(context)
           ~~~~~~~~~~~^^^^^^^^^
  File "/home/s1gm9/Documents/Projects/DIGIMANAGER/venv/lib/python3.13/site-packages/django/template/loader_tags.py", line 65, in render
    result = block.nodelist.render(context)
  File "/home/s1gm9/Documents/Projects/DIGIMANAGER/venv/lib/python3.13/site-packages/django/template/base.py", line 1008, in render
    return SafeString("".join([node.render_annotated(context) for node in self]))
                               ~~~~~~~~~~~~~~~~~~~~~^^^^^^^^^
  File "/home/s1gm9/Documents/Projects/DIGIMANAGER/venv/lib/python3.13/site-packages/django/template/base.py", line 969, in render_annotated
    return self.render(context)
           ~~~~~~~~~~~^^^^^^^^^
  File "/home/s1gm9/Documents/Projects/DIGIMANAGER/venv/lib/python3.13/site-packages/django/template/defaulttags.py", line 243, in render
    nodelist.append(node.render_annotated(context))
                    ~~~~~~~~~~~~~~~~~~~~~^^^^^^^^^
  File "/home/s1gm9/Documents/Projects/DIGIMANAGER/venv/lib/python3.13/site-packages/django/template/base.py", line 969, in render_annotated
    return self.render(context)
           ~~~~~~~~~~~^^^^^^^^^
  File "/home/s1gm9/Documents/Projects/DIGIMANAGER/venv/lib/python3.13/site-packages/django/template/defaulttags.py", line 480, in render
    url = reverse(view_name, args=args, kwargs=kwargs, current_app=current_app)
  File "/home/s1gm9/Documents/Projects/DIGIMANAGER/venv/lib/python3.13/site-packages/django/urls/base.py", line 88, in reverse
    return resolver._reverse_with_prefix(view, prefix, *args, **kwargs)
           ~~~~~~~~~~~~~~~~~~~~~~~~~~~~~^^^^^^^^^^^^^^^^^^^^^^^^^^^^^^^
  File "/home/s1gm9/Documents/Projects/DIGIMANAGER/venv/lib/python3.13/site-packages/django/urls/resolvers.py", line 831, in _reverse_with_prefix
    raise NoReverseMatch(msg)
django.urls.exceptions.NoReverseMatch: Reverse for 'editPlatform' with arguments '(4,)' not found. 1 pattern(s) tried: ['platforms/edit/\\Z']
"GET /platforms/manage/ HTTP/1.1" 500 177139
Internal Server Error: /register/
Traceback (most recent call last):
  File "/home/s1gm9/Documents/Projects/DIGIMANAGER/venv/lib/python3.13/site-packages/django/core/handlers/exception.py", line 55, in inner
    response = get_response(request)
  File "/home/s1gm9/Documents/Projects/DIGIMANAGER/venv/lib/python3.13/site-packages/django/core/handlers/base.py", line 197, in _get_response
    response = wrapped_callback(request, *callback_args, **callback_kwargs)
  File "/home/s1gm9/Documents/Projects/DIGIMANAGER/DIGIMANAGER/scheduler/views.py", line 156, in register
    return render(request, 'users/register.html', {'form': form})
  File "/home/s1gm9/Documents/Projects/DIGIMANAGER/venv/lib/python3.13/site-packages/django/shortcuts.py", line 25, in render
    content = loader.render_to_string(template_name, context, request, using=using)
  File "/home/s1gm9/Documents/Projects/DIGIMANAGER/venv/lib/python3.13/site-packages/django/template/loader.py", line 61, in render_to_string
    template = get_template(template_name, using=using)
  File "/home/s1gm9/Documents/Projects/DIGIMANAGER/venv/lib/python3.13/site-packages/django/template/loader.py", line 15, in get_template
    return engine.get_template(template_name)
           ~~~~~~~~~~~~~~~~~~~^^^^^^^^^^^^^^^
  File "/home/s1gm9/Documents/Projects/DIGIMANAGER/venv/lib/python3.13/site-packages/django/template/backends/django.py", line 79, in get_template
    return Template(self.engine.get_template(template_name), self)
                    ~~~~~~~~~~~~~~~~~~~~~~~~^^^^^^^^^^^^^^^
  File "/home/s1gm9/Documents/Projects/DIGIMANAGER/venv/lib/python3.13/site-packages/django/template/engine.py", line 177, in get_template
    template, origin = self.find_template(template_name)
                       ~~~~~~~~~~~~~~~~~~^^^^^^^^^^^^^^^
  File "/home/s1gm9/Documents/Projects/DIGIMANAGER/venv/lib/python3.13/site-packages/django/template/engine.py", line 159, in find_template
    template = loader.get_template(name, skip=skip)
  File "/home/s1gm9/Documents/Projects/DIGIMANAGER/venv/lib/python3.13/site-packages/django/template/loaders/cached.py", line 57, in get_template
    template = super().get_template(template_name, skip)
  File "/home/s1gm9/Documents/Projects/DIGIMANAGER/venv/lib/python3.13/site-packages/django/template/loaders/base.py", line 28, in get_template
    return Template(
        contents,
    ...<2 lines>...
        self.engine,
    )
  File "/home/s1gm9/Documents/Projects/DIGIMANAGER/venv/lib/python3.13/site-packages/django/template/base.py", line 154, in __init__
    self.nodelist = self.compile_nodelist()
                    ~~~~~~~~~~~~~~~~~~~~~^^
  File "/home/s1gm9/Documents/Projects/DIGIMANAGER/venv/lib/python3.13/site-packages/django/template/base.py", line 196, in compile_nodelist
    nodelist = parser.parse()
  File "/home/s1gm9/Documents/Projects/DIGIMANAGER/venv/lib/python3.13/site-packages/django/template/base.py", line 518, in parse
    raise self.error(token, e)
  File "/home/s1gm9/Documents/Projects/DIGIMANAGER/venv/lib/python3.13/site-packages/django/template/base.py", line 516, in parse
    compiled_result = compile_func(self, token)
  File "/home/s1gm9/Documents/Projects/DIGIMANAGER/venv/lib/python3.13/site-packages/django/template/loader_tags.py", line 295, in do_extends
    nodelist = parser.parse()
  File "/home/s1gm9/Documents/Projects/DIGIMANAGER/venv/lib/python3.13/site-packages/django/template/base.py", line 518, in parse
    raise self.error(token, e)
  File "/home/s1gm9/Documents/Projects/DIGIMANAGER/venv/lib/python3.13/site-packages/django/template/base.py", line 516, in parse
    compiled_result = compile_func(self, token)
  File "/home/s1gm9/Documents/Projects/DIGIMANAGER/venv/lib/python3.13/site-packages/django/template/loader_tags.py", line 234, in do_block
    nodelist = parser.parse(("endblock",))
  File "/home/s1gm9/Documents/Projects/DIGIMANAGER/venv/lib/python3.13/site-packages/django/template/base.py", line 489, in parse
    raise self.error(token, e)
  File "/home/s1gm9/Documents/Projects/DIGIMANAGER/venv/lib/python3.13/site-packages/django/template/base.py", line 487, in parse
    filter_expression = self.compile_filter(token.contents)
  File "/home/s1gm9/Documents/Projects/DIGIMANAGER/venv/lib/python3.13/site-packages/django/template/base.py", line 605, in compile_filter
    return FilterExpression(token, self)
  File "/home/s1gm9/Documents/Projects/DIGIMANAGER/venv/lib/python3.13/site-packages/django/template/base.py", line 701, in __init__
    filter_func = parser.find_filter(filter_name)
  File "/home/s1gm9/Documents/Projects/DIGIMANAGER/venv/lib/python3.13/site-packages/django/template/base.py", line 611, in find_filter
    raise TemplateSyntaxError("Invalid filter: '%s'" % filter_name)
django.template.exceptions.TemplateSyntaxError: Invalid filter: 'crispy'
"GET /register/ HTTP/1.1" 500 178897
Internal Server Error: /posts/create/
Traceback (most recent call last):
  File "/home/s1gm9/Documents/Projects/DIGIMANAGER/venv/lib/python3.13/site-packages/django/core/handlers/exception.py", line 55, in inner
    response = get_response(request)
  File "/home/s1gm9/Documents/Projects/DIGIMANAGER/venv/lib/python3.13/site-packages/django/core/handlers/base.py", line 197, in _get_response
    response = wrapped_callback(request, *callback_args, **callback_kwargs)
  File "/home/s1gm9/Documents/Projects/DIGIMANAGER/venv/lib/python3.13/site-packages/django/contrib/auth/decorators.py", line 60, in _view_wrapper
    return view_func(request, *args, **kwargs)
  File "/home/s1gm9/Documents/Projects/DIGIMANAGER/DIGIMANAGER/scheduler/views.py", line 255, in createPost
    publishPost.apply_async((post.id,), countdown=eta)
    ^^^^^^^^^^^
NameError: name 'publishPost' is not defined
"POST /posts/create/ HTTP/1.1" 500 77287
Internal Server Error: /post/5/edit/
Traceback (most recent call last):
  File "/home/s1gm9/Documents/Projects/DIGIMANAGER/venv/lib/python3.13/site-packages/django/core/handlers/exception.py", line 55, in inner
    response = get_response(request)
  File "/home/s1gm9/Documents/Projects/DIGIMANAGER/venv/lib/python3.13/site-packages/django/core/handlers/base.py", line 197, in _get_response
    response = wrapped_callback(request, *callback_args, **callback_kwargs)
  File "/home/s1gm9/Documents/Projects/DIGIMANAGER/venv/lib/python3.13/site-packages/django/contrib/auth/decorators.py", line 60, in _view_wrapper
    return view_func(request, *args, **kwargs)
  File "/home/s1gm9/Documents/Projects/DIGIMANAGER/DIGIMANAGER/scheduler/views.py", line 298, in editPost
    schedule_post(updated_post)
    ~~~~~~~~~~~~~^^^^^^^^^^^^^^
  File "/home/s1gm9/Documents/Projects/DIGIMANAGER/DIGIMANAGER/scheduler/scheduling.py", line 7, in schedule_post
    PeriodicTask.objects.create(
    ~~~~~~~~~~~~~~~~~~~~~~~~~~~^
        clocked=clocked,
        ^^^^^^^^^^^^^^^^
    ...<3 lines>...
        one_off=True
        ^^^^^^^^^^^^
    )
    ^
  File "/home/s1gm9/Documents/Projects/DIGIMANAGER/venv/lib/python3.13/site-packages/django/db/models/manager.py", line 87, in manager_method
    return getattr(self.get_queryset(), name)(*args, **kwargs)
           ~~~~~~~~~~~~~~~~~~~~~~~~~~~~~~~~~~^^^^^^^^^^^^^^^^^
  File "/home/s1gm9/Documents/Projects/DIGIMANAGER/venv/lib/python3.13/site-packages/django/db/models/query.py", line 679, in create
    obj.save(force_insert=True, using=self.db)
    ~~~~~~~~^^^^^^^^^^^^^^^^^^^^^^^^^^^^^^^^^^
  File "/home/s1gm9/Documents/Projects/DIGIMANAGER/venv/lib/python3.13/site-packages/django_celery_beat/models.py", line 627, in save
    self.validate_unique()
    ~~~~~~~~~~~~~~~~~~~~^^
  File "/home/s1gm9/Documents/Projects/DIGIMANAGER/venv/lib/python3.13/site-packages/django_celery_beat/models.py", line 594, in validate_unique
    super().validate_unique(*args, **kwargs)
    ~~~~~~~~~~~~~~~~~~~~~~~^^^^^^^^^^^^^^^^^
  File "/home/s1gm9/Documents/Projects/DIGIMANAGER/venv/lib/python3.13/site-packages/django/db/models/base.py", line 1385, in validate_unique
    raise ValidationError(errors)
django.core.exceptions.ValidationError: {'name': ['Periodic task with this Name already exists.']}
"POST /post/5/edit/ HTTP/1.1" 500 103556
